Workbook

Sheet Samenvatting
A1: EMC — prijsvoorstel (AUD), 24-9-2026 — gedifferentieerd
A2: Benchmark: Julia Raven (juliaraven.com, AU/NZ, AUD), product export 24-9-2026. Let op: Julia Raven is een damesstore met 84 herenproducten — herencategorieën zijn dun (n 1–23). Waar herendata ontbreekt (shirts, polos, sweaters, sandalen, swimwear) is de damescategorie als proxy gebruikt; dat staat per regel in kolom L.
A3: Regel: per groep tussen het onderste kwartiel (P25) en de mediaan van Julia Raven, max +A$20 per product. Grootste stappen waar EMC het verst onder de markt zit (loafers, nette schoenen, overhemden, jeans). Shorts en swimwear ongewijzigd: Julia Raven zit daar zelf op A$54,95. T-shirts/polos +A$5. Compare-at houdt per product het huidige kortingspercentage.
A4: Gele cellen op tabblad Voorstel (kolom I) mag je aanpassen; compare-at, verhoging en "nog onder JR-mediaan" rekenen mee.
A6: Groep | B6: Aantal | C6: Prijs nu (gem.) | D6: Voorstel (gem.) | E6: Verhoging (gem.) | F6: JR P25 | G6: JR mediaan | H6: Nog onder JR-mediaan | I6: Julia Raven-referentie | J6: JR n
A7: Men's Trousers | B7: =COUNTIF(Voorstel!$C$2:$C$342,A7) -> 59 | C7: =AVERAGEIF(Voorstel!$C$2:$C$342,A7,Voorstel!$F$2:$F$342) -> 64.95 | D7: =AVERAGEIF(Voorstel!$C$2:$C$342,A7,Voorstel!$I$2:$I$342) -> 69.95 | E7: =D7-C7 -> 5 | F7: 66.2 | G7: 69.95 | H7: =G7-D7 -> 0 | I7: JR men's trousers | J7: 6
A8: Men's Shorts | B8: =COUNTIF(Voorstel!$C$2:$C$342,A8) -> 58 | C8: =AVERAGEIF(Voorstel!$C$2:$C$342,A8,Voorstel!$F$2:$F$342) -> 54.95 | D8: =AVERAGEIF(Voorstel!$C$2:$C$342,A8,Voorstel!$I$2:$I$342) -> 54.95 | E8: =D8-C8 -> 0 | F8: 54.95 | G8: 54.95 | H8: =G8-D8 -> 0 | I8: JR men's shorts | J8: 6
A9: Shirts — T-shirts & polos | B9: =COUNTIF(Voorstel!$C$2:$C$342,A9) -> 39 | C9: =AVERAGEIF(Voorstel!$C$2:$C$342,A9,Voorstel!$F$2:$F$342) -> 57.001282 | D9: =AVERAGEIF(Voorstel!$C$2:$C$342,A9,Voorstel!$I$2:$I$342) -> 59.95 | E9: =D9-C9 -> 2.9487179 | F9: 64.95 | G9: 69.95 | H9: =G9-D9 -> 10 | I9: geen JR-herendata; proxy tank tops (dames) | J9: 16
A10: Shirts — Overhemden & rugby | B10: =COUNTIF(Voorstel!$C$2:$C$342,A10) -> 36 | C10: =AVERAGEIF(Voorstel!$C$2:$C$342,A10,Voorstel!$F$2:$F$342) -> 59.533333 | D10: =AVERAGEIF(Voorstel!$C$2:$C$342,A10,Voorstel!$I$2:$I$342) -> 69.95 | E10: =D10-C10 -> 10.416667 | F10: 79.95 | G10: 84.95 | H10: =G10-D10 -> 15 | I10: JR men's shirt n=1 (64,95); proxy blouses (dames) | J10: 14
A11: Shoes — Loafers | B11: =COUNTIF(Voorstel!$C$2:$C$342,A11) -> 35 | C11: =AVERAGEIF(Voorstel!$C$2:$C$342,A11,Voorstel!$F$2:$F$342) -> 74.95 | D11: =AVERAGEIF(Voorstel!$C$2:$C$342,A11,Voorstel!$I$2:$I$342) -> 89.95 | E11: =D11-C11 -> 15 | F11: 112.45 | G11: 124.95 | H11: =G11-D11 -> 35 | I11: JR men's loafers (3: 99,95–124,95); dames flats & loafers P25 94,95 | J11: 3
A12: Men's Hoodies | B12: =COUNTIF(Voorstel!$C$2:$C$342,A12) -> 17 | C12: =AVERAGEIF(Voorstel!$C$2:$C$342,A12,Voorstel!$F$2:$F$342) -> 69.95 | D12: =AVERAGEIF(Voorstel!$C$2:$C$342,A12,Voorstel!$I$2:$I$342) -> 74.95 | E12: =D12-C12 -> 5 | F12: 69.95 | G12: 74.95 | H12: =G12-D12 -> 0 | I12: JR men's hoodies | J12: 9
A13: Men's Jeans | B13: =COUNTIF(Voorstel!$C$2:$C$342,A13) -> 16 | C13: =AVERAGEIF(Voorstel!$C$2:$C$342,A13,Voorstel!$F$2:$F$342) -> 64.95 | D13: =AVERAGEIF(Voorstel!$C$2:$C$342,A13,Voorstel!$I$2:$I$342) -> 74.95 | E13: =D13-C13 -> 10 | F13: 68.7 | G13: 82.45 | H13: =G13-D13 -> 7.5 | I13: JR men's jeans | J13: 6
A14: Men's Sandals | B14: =COUNTIF(Voorstel!$C$2:$C$342,A14) -> 16 | C14: =AVERAGEIF(Voorstel!$C$2:$C$342,A14,Voorstel!$F$2:$F$342) -> 54.95 | D14: =AVERAGEIF(Voorstel!$C$2:$C$342,A14,Voorstel!$I$2:$I$342) -> 59.95 | E14: =D14-C14 -> 5 | F14: 64.95 | G14: 64.95 | H14: =G14-D14 -> 5 | I14: JR men's sandals n=1 (94,95); proxy sandals (dames) | J14: 22
A15: Men's Jackets & Coats | B15: =COUNTIF(Voorstel!$C$2:$C$342,A15) -> 16 | C15: =AVERAGEIF(Voorstel!$C$2:$C$342,A15,Voorstel!$F$2:$F$342) -> 89.95 | D15: =AVERAGEIF(Voorstel!$C$2:$C$342,A15,Voorstel!$I$2:$I$342) -> 94.95 | E15: =D15-C15 -> 5 | F15: 89.95 | G15: 99.95 | H15: =G15-D15 -> 5 | I15: JR men's jackets | J15: 13
A16: Shoes — Sneakers & casual | B16: =COUNTIF(Voorstel!$C$2:$C$342,A16) -> 13 | C16: =AVERAGEIF(Voorstel!$C$2:$C$342,A16,Voorstel!$F$2:$F$342) -> 72.642308 | D16: =AVERAGEIF(Voorstel!$C$2:$C$342,A16,Voorstel!$I$2:$I$342) -> 74.95 | E16: =D16-C16 -> 2.3076923 | F16: 64.95 | G16: 79.95 | H16: =G16-D16 -> 5 | I16: JR men's sneakers/casual | J16: 23
A17: Men's Swimwear | B17: =COUNTIF(Voorstel!$C$2:$C$342,A17) -> 12 | C17: =AVERAGEIF(Voorstel!$C$2:$C$342,A17,Voorstel!$F$2:$F$342) -> 54.95 | D17: =AVERAGEIF(Voorstel!$C$2:$C$342,A17,Voorstel!$I$2:$I$342) -> 54.95 | E17: =D17-C17 -> 0 | F17: 49.95 | G17: 52.45 | H17: =G17-D17 -> -2.5 | I17: geen JR-herendata; proxy swimwear (dames) | J17: 6
A18: Shoes — Dress shoes | B18: =COUNTIF(Voorstel!$C$2:$C$342,A18) -> 8 | C18: =AVERAGEIF(Voorstel!$C$2:$C$342,A18,Voorstel!$F$2:$F$342) -> 84.95 | D18: =AVERAGEIF(Voorstel!$C$2:$C$342,A18,Voorstel!$I$2:$I$342) -> 99.95 | E18: =D18-C18 -> 15 | F18: 104.95 | G18: 104.95 | H18: =G18-D18 -> 5 | I18: JR men's dress shoes (oxford/derby) | J18: 3
... A23: Trousers — instap | B23: =COUNTIF(Voorstel!$C$2:$C$342,A23) -> 1 | C23: =AVERAGEIF(Voorstel!$C$2:$C$342,A23,Voorstel!$F$2:$F$342) -> 54.95 | D23: =AVERAGEIF(Voorstel!$C$2:$C$342,A23,Voorstel!$I$2:$I$342) -> 64.95 | E23: =D23-C23 -> 10 | F23: 66.2 | G23: 69.95 | H23: =G23-D23 -> 5 | I23: JR men's trousers | J23: 6
A25: Alle producten | B25: =SUM(B7:B23) -> 341 | C25: =AVERAGE(Voorstel!$F$2:$F$342) -> 64.202199 | D25: =AVERAGE(Voorstel!$I$2:$I$342) -> 69.876686 | E25: =D25-C25 -> 5.6744868 | G25: =AVERAGE(Voorstel!$O$2:$O$342) -> 77.384018 | H25: =G25-D25 -> 7.5073314
A27: Gemiddelde verhoging | C27: =D25/C25-1 -> 0.088384617
A28: Producten ongewijzigd | C28: =COUNTIF(Voorstel!$K$2:$K$342,0) -> 98
A29: Producten +A$5 | C29: =COUNTIF(Voorstel!$K$2:$K$342,5) -> 146
A30: Producten +A$10 | C30: =COUNTIF(Voorstel!$K$2:$K$342,10) -> 50
A31: Producten +A$15 | C31: =COUNTIF(Voorstel!$K$2:$K$342,15) -> 47
A33: Kanttekeningen
A34: • EMC is op 21-9 al verlaagd (gem. A$72,75 → 64,20). Dit voorstel zet de groepen die het verst onder de markt zitten terug omhoog: loafers 74,95 → 89,95 (was 89,95 vóór 21-9), nette schoenen 84,95 → 99,95 (was 99,95), jeans 64,95 → 74,95, overhemden 59,95 → 69,95.
A35: • Julia Raven heeft slechts 84 herenproducten. Voor shorts (n=6, allemaal 49,95–54,95) en sneakers (P25 64,95) zit EMC al op hun niveau; daarom daar 0 of +5.
A36: • 2 damesschoenen in de herenstore ("Brown Slip On Shoe For Women", "Casual Shoe For Women") gaan mee in hun schoenengroep; nog steeds opruimen (zie doc 16).
A37: • Doorvoeren in één batch via de Shopify-connector (productVariantsBulkUpdate, prijs + compare-at, alle varianten). Daarna 14 dagen meten.

Sheet Voorstel
A1: Handle | B1: Titel | C1: Groep | D1: Type (Shopify) | E1: Varianten | F1: Prijs nu | G1: Compare-at nu | H1: Korting nu | I1: Voorstel: prijs | J1: Voorstel: compare-at | K1: Verhoging | L1: Julia Raven-referentie | M1: JR n | N1: JR P25 | O1: JR mediaan | P1: Nog onder JR-mediaan
A2: mens-cable-knit-sweatshirt-quarter-zip-collar-ribbed-hem-knit | B2: Men's Cable Knit Sweatshirt | Quarter-Zip Collar Ribbed Hem Knit | C2: Men's Hoodies | D2: Hoodies | E2: 35 | F2: 69.95 | G2: 116.95 | H2: =1-F2/G2 -> 0.40188115 | I2: 74.95 | J2: =ROUNDUP(I2/(1-H2),0)-0.05 -> 125.95 | K2: =I2-F2 -> 5 | L2: JR men's hoodies | M2: 9 | N2: 69.95 | O2: 74.95 | P2: =O2-I2 -> 0
A3: mens-hooded-sweatshirt-full-zip-knit-relaxed-fit-pockets | B3: Men's Hooded Sweatshirt | Full Zip Knit Relaxed Fit Pockets | C3: Men's Hoodies | D3: Hoodies | E3: 28 | F3: 69.95 | G3: 139.95 | H3: =1-F3/G3 -> 0.50017864 | I3: 74.95 | J3: =ROUNDUP(I3/(1-H3),0)-0.05 -> 149.95 | K3: =I3-F3 -> 5 | L3: JR men's hoodies | M3: 9 | N3: 69.95 | O3: 74.95 | P3: =O3-I3 -> 0
A4: mens-hoodie-half-zip-pullover-fleece-knit | B4: Men's Hoodie | Half Zip Pullover Fleece Knit | C4: Men's Hoodies | D4: Men's Jacket | E4: 72 | F4: 69.95 | G4: 116.95 | H4: =1-F4/G4 -> 0.40188115 | I4: 74.95 | J4: =ROUNDUP(I4/(1-H4),0)-0.05 -> 125.95 | K4: =I4-F4 -> 5 | L4: JR men's hoodies | M4: 9 | N4: 69.95 | O4: 74.95 | P4: =O4-I4 -> 0
A5: mens-hoodie-pullover-hood-drawstring-kangaroo-pocket-knit | B5: Men's Hoodie | Pullover Hood Drawstring Kangaroo Pocket Knit | C5: Men's Hoodies | D5: Hoodie | E5: 35 | F5: 69.95 | G5: 116.95 | H5: =1-F5/G5 -> 0.40188115 | I5: 74.95 | J5: =ROUNDUP(I5/(1-H5),0)-0.05 -> 125.95 | K5: =I5-F5 -> 5 | L5: JR men's hoodies | M5: 9 | N5: 69.95 | O5: 74.95 | P5: =O5-I5 -> 0
A6: mens-hoodie-quarter-button-ribbed-knit-elbow-patch | B6: Men's Hoodie | Quarter-Button Ribbed Knit Elbow Patch | C6: Men's Hoodies | D6: Sweatshirts | E6: 42 | F6: 69.95 | G6: 127.95 | H6: =1-F6/G6 -> 0.45330207 | I6: 74.95 | J6: =ROUNDUP(I6/(1-H6),0)-0.05 -> 137.95 | K6: =I6-F6 -> 5 | L6: JR men's hoodies | M6: 9 | N6: 69.95 | O6: 74.95 | P6: =O6-I6 -> 0
A7: mens-hoodie-quarter-zip-hood-cargo-pockets-knit | B7: Men's Hoodie | Quarter-Zip Hood Cargo Pockets Knit | C7: Men's Hoodies | D7: Hoodies | E7: 56 | F7: 69.95 | G7: 127.95 | H7: =1-F7/G7 -> 0.45330207 | I7: 74.95 | J7: =ROUNDUP(I7/(1-H7),0)-0.05 -> 137.95 | K7: =I7-F7 -> 5 | L7: JR men's hoodies | M7: 9 | N7: 69.95 | O7: 74.95 | P7: =O7-I7 -> 0
A8: mens-hoodie-zip-closure-hood-knit-reversible | B8: Men's Hoodie | Zip Closure Hood Knit Reversible | C8: Men's Hoodies | D8: Clothing | E8: 35 | F8: 69.95 | G8: 139.95 | H8: =1-F8/G8 -> 0.50017864 | I8: 74.95 | J8: =ROUNDUP(I8/(1-H8),0)-0.05 -> 149.95 | K8: =I8-F8 -> 5 | L8: JR men's hoodies | M8: 9 | N8: 69.95 | O8: 74.95 | P8: =O8-I8 -> 0
A9: mens-hoodie-zip-up-front-side-pockets-knit | B9: Men's Hoodie | Zip-Up Front Side Pockets Knit | C9: Men's Hoodies | D9: hoodies | E9: 15 | F9: 69.95 | G9: 139.95 | H9: =1-F9/G9 -> 0.50017864 | I9: 74.95 | J9: =ROUNDUP(I9/(1-H9),0)-0.05 -> 149.95 | K9: =I9-F9 -> 5 | L9: JR men's hoodies | M9: 9 | N9: 69.95 | O9: 74.95 | P9: =O9-I9 -> 0
A10: mens-hoodie-zip-up-knit-drawstring-hood-multiple-pockets | B10: Men's Hoodie | Zip-Up Knit Drawstring Hood Multiple Pockets | C10: Men's Hoodies | D10: Hoodies | E10: 56 | F10: 69.95 | G10: 116.95 | H10: =1-F10/G10 -> 0.40188115 | I10: 74.95 | J10: =ROUNDUP(I10/(1-H10),0)-0.05 -> 125.95 | K10: =I10-F10 -> 5 | L10: JR men's hoodies | M10: 9 | N10: 69.95 | O10: 74.95 | P10: =O10-I10 -> 0
A11: mens-sweatshirt-fleece-zip-up-hooded-long-sleeve | B11: Men's Sweatshirt | Fleece Zip-Up Hooded Long Sleeve | C11: Men's Hoodies | D11: Men's Jacket | E11: 28 | F11: 69.95 | G11: 139.95 | H11: =1-F11/G11 -> 0.50017864 | I11: 74.95 | J11: =ROUNDUP(I11/(1-H11),0)-0.05 -> 149.95 | K11: =I11-F11 -> 5 | L11: JR men's hoodies | M11: 9 | N11: 69.95 | O11: 74.95 | P11: =O11-I11 -> 0
A12: mens-sweatshirt-half-zip-high-neck-knit | B12: Men's Sweatshirt | Half Zip High Neck Knit | C12: Men's Hoodies | D12: Hoodies | E12: 42 | F12: 69.95 | G12: 139.95 | H12: =1-F12/G12 -> 0.50017864 | I12: 74.95 | J12: =ROUNDUP(I12/(1-H12),0)-0.05 -> 149.95 | K12: =I12-F12 -> 5 | L12: JR men's hoodies | M12: 9 | N12: 69.95 | O12: 74.95 | P12: =O12-I12 -> 0
A13: mens-sweatshirt-polo-collar-drop-shoulder-garment-washed | B13: Men's Sweatshirt | Polo Collar Drop Shoulder Garment Washed | C13: Men's Hoodies | D13: mvbtool | E13: 36 | F13: 69.95 | G13: 139.95 | H13: =1-F13/G13 -> 0.50017864 | I13: 74.95 | J13: =ROUNDUP(I13/(1-H13),0)-0.05 -> 149.95 | K13: =I13-F13 -> 5 | L13: JR men's hoodies | M13: 9 | N13: 69.95 | O13: 74.95 | P13: =O13-I13 -> 0
... A165: mens-chino-regular-fit-straight-leg-zip-fly-button-closure | B165: Men's Chino | Regular Fit Straight Leg Zip Fly Button Closure | C165: Men's Trousers | D165: New4 | E165: 16 | F165: 64.95 | G165: 108.95 | H165: =1-F165/G165 -> 0.40385498 | I165: 69.95 | J165: =ROUNDUP(I165/(1-H165),0)-0.05 -> 117.95 | K165: =I165-F165 -> 5 | L165: JR men's trousers | M165: 6 | N165: 66.2 | O165: 69.95 | P165: =O165-I165 -> 0
A166: mens-chino-slim-fit-flat-front-stretch | B166: Men's Chino | Slim Fit Flat Front Stretch | C166: Men's Trousers | E166: 35 | F166: 64.95 | G166: 108.95 | H166: =1-F166/G166 -> 0.40385498 | I166: 69.95 | J166: =ROUNDUP(I166/(1-H166),0)-0.05 -> 117.95 | K166: =I166-F166 -> 5 | L166: JR men's trousers | M166: 6 | N166: 66.2 | O166: 69.95 | P166: =O166-I166 -> 0
A167: mens-chino-slim-fit-plaid-tapered-closure | B167: Men's Chino | Slim Fit Plaid Tapered Closure | C167: Men's Trousers | E167: 28 | F167: 64.95 | G167: 108.95 | H167: =1-F167/G167 -> 0.40385498 | I167: 69.95 | J167: =ROUNDUP(I167/(1-H167),0)-0.05 -> 117.95 | K167: =I167-F167 -> 5 | L167: JR men's trousers | M167: 6 | N167: 66.2 | O167: 69.95 | P167: =O167-I167 -> 0
A168: mens-chino-slim-fit-mid-rise-button-closure | B168: Men's Chino | Slim-Fit Mid-Rise Button Closure | C168: Men's Trousers | D168: pants | E168: 56 | F168: 64.95 | G168: 118.95 | H168: =1-F168/G168 -> 0.45397226 | I168: 69.95 | J168: =ROUNDUP(I168/(1-H168),0)-0.05 -> 128.95 | K168: =I168-F168 -> 5 | L168: JR men's trousers | M168: 6 | N168: 66.2 | O168: 69.95 | P168: =O168-I168 -> 0
A169: mens-chino-tapered-drawstring-pleated-front | B169: Men's Chino | Tapered Drawstring Pleated Front | C169: Men's Trousers | D169: Trousers | E169: 42 | F169: 64.95 | G169: 118.95 | H169: =1-F169/G169 -> 0.45397226 | I169: 69.95 | J169: =ROUNDUP(I169/(1-H169),0)-0.05 -> 128.95 | K169: =I169-F169 -> 5 | L169: JR men's trousers | M169: 6 | N169: 66.2 | O169: 69.95 | P169: =O169-I169 -> 0
A170: mens-dress-pants-slim-fit-tapered-wool-blend | B170: Men's Dress Pants | Slim Fit Tapered Wool Blend | C170: Men's Trousers | D170: Trousers | E170: 80 | F170: 64.95 | G170: 108.95 | H170: =1-F170/G170 -> 0.40385498 | I170: 69.95 | J170: =ROUNDUP(I170/(1-H170),0)-0.05 -> 117.95 | K170: =I170-F170 -> 5 | L170: JR men's trousers | M170: 6 | N170: 66.2 | O170: 69.95 | P170: =O170-I170 -> 0
A171: mens-dress-pants-tapered-leg-pleated-front-wool-blend | B171: Men's Dress Pants | Tapered Leg Pleated Front Wool Blend | C171: Men's Trousers | D171: Straight Leg Pants | E171: 18 | F171: 64.95 | G171: 108.95 | H171: =1-F171/G171 -> 0.40385498 | I171: 69.95 | J171: =ROUNDUP(I171/(1-H171),0)-0.05 -> 117.95 | K171: =I171-F171 -> 5 | L171: JR men's trousers | M171: 6 | N171: 66.2 | O171: 69.95 | P171: =O171-I171 -> 0
A172: mens-dress-pants-tweed-relaxed-fit-straight-leg | B172: Men's Dress Pants | Tweed Relaxed Fit Straight Leg | C172: Men's Trousers | D172: Straight Leg Pants | E172: 48 | F172: 64.95 | G172: 108.95 | H172: =1-F172/G172 -> 0.40385498 | I172: 69.95 | J172: =ROUNDUP(I172/(1-H172),0)-0.05 -> 117.95 | K172: =I172-F172 -> 5 | L172: JR men's trousers | M172: 6 | N172: 66.2 | O172: 69.95 | P172: =O172-I172 -> 0
A173: mens-dress-pants-waffle-knit-pleated-tapered | B173: Men's Dress Pants | Waffle Knit Pleated Tapered | C173: Men's Trousers | D173: Trousers | E173: 21 | F173: 64.95 | G173: 118.95 | H173: =1-F173/G173 -> 0.45397226 | I173: 69.95 | J173: =ROUNDUP(I173/(1-H173),0)-0.05 -> 128.95 | K173: =I173-F173 -> 5 | L173: JR men's trousers | M173: 6 | N173: 66.2 | O173: 69.95 | P173: =O173-I173 -> 0
A174: mens-high-waisted-pants-pleated-straight-fit-gurkha | B174: Men's High Waisted Pants | Pleated Straight Fit Gurkha | C174: Men's Trousers | D174: Pants | E174: 14 | F174: 64.95 | G174: 108.95 | H174: =1-F174/G174 -> 0.40385498 | I174: 69.95 | J174: =ROUNDUP(I174/(1-H174),0)-0.05 -> 117.95 | K174: =I174-F174 -> 5 | L174: JR men's trousers | M174: 6 | N174: 66.2 | O174: 69.95 | P174: =O174-I174 -> 0
A175: mens-high-waisted-pants-pleated-straight-leg-tailored | B175: Men's High Waisted Pants | Pleated Straight Leg Tailored | C175: Men's Trousers | D175: Pants | E175: 28 | F175: 64.95 | G175: 108.95 | H175: =1-F175/G175 -> 0.40385498 | I175: 69.95 | J175: =ROUNDUP(I175/(1-H175),0)-0.05 -> 117.95 | K175: =I175-F175 -> 5 | L175: JR men's trousers | M175: 6 | N175: 66.2 | O175: 69.95 | P175: =O175-I175 -> 0
A176: mens-high-waisted-pants-relaxed-fit-cargo-pockets-cotton | B176: Men's High Waisted Pants | Relaxed Fit Cargo Pockets Cotton | C176: Men's Trousers | D176: Cargo Pants | E176: 30 | F176: 64.95 | G176: 129.95 | H176: =1-F176/G176 -> 0.50019238 | I176: 69.95 | J176: =ROUNDUP(I176/(1-H176),0)-0.05 -> 139.95 | K176: =I176-F176 -> 5 | L176: JR men's trousers | M176: 6 | N176: 66.2 | O176: 69.95 | P176: =O176-I176 -> 0
A177: mens-high-waisted-pants-relaxed-fit-linen-lightweight | B177: Men's High Waisted Pants | Relaxed Fit Linen Lightweight | C177: Men's Trousers | D177: Trousers | E177: 35 | F177: 64.95 | G177: 108.95 | H177: =1-F177/G177 -> 0.40385498 | I177: 69.95 | J177: =ROUNDUP(I177/(1-H177),0)-0.05 -> 117.95 | K177: =I177-F177 -> 5 | L177: JR men's trousers | M177: 6 | N177: 66.2 | O177: 69.95 | P177: =O177-I177 -> 0
A178: mens-hiking-pants-cargo-pockets-quick-dry-regular-fit | B178: Men's Hiking Pants | Cargo Pockets Quick Dry Regular Fit | C178: Men's Trousers | D178: Men's Trousers | E178: 49 | F178: 64.95 | G178: 108.95 | H178: =1-F178/G178 -> 0.40385498 | I178: 69.95 | J178: =ROUNDUP(I178/(1-H178),0)-0.05 -> 117.95 | K178: =I178-F178 -> 5 | L178: JR men's trousers | M178: 6 | N178: 66.2 | O178: 69.95 | P178: =O178-I178 -> 0
A179: mens-hiking-pants-cargo-pockets-reinforced-knees-straight-leg | B179: Men's Hiking Pants | Cargo Pockets Reinforced Knees Straight Leg | C179: Men's Trousers | D179: Broeken | E179: 28 | F179: 64.95 | G179: 108.95 | H179: =1-F179/G179 -> 0.40385498 | I179: 69.95 | J179: =ROUNDUP(I179/(1-H179),0)-0.05 -> 117.95 | K179: =I179-F179 -> 5 | L179: JR men's trousers | M179: 6 | N179: 66.2 | O179: 69.95 | P179: =O179-I179 -> 0
... A254: mens-henley-three-button-placket-roll-tab-sleeves-linen | B254: Men's Henley | Three Button Placket Roll Tab Sleeves Linen | C254: Shirts — T-shirts & polos | D254: Clothing | E254: 63 | F254: 54.95 | G254: 99.95 | H254: =1-F254/G254 -> 0.45022511 | I254: 59.95 | J254: =ROUNDUP(I254/(1-H254),0)-0.05 -> 109.95 | K254: =I254-F254 -> 5 | L254: geen JR-herendata; proxy tank tops (dames) | M254: 16 | N254: 64.95 | O254: 69.95 | P254: =O254-I254 -> 10
A255: mens-long-sleeve-henley-henley-neckline-button-closure-knit | B255: Men's Long Sleeve Henley | Henley Neckline Button Closure Knit | C255: Shirts — T-shirts & polos | E255: 49 | F255: 54.95 | G255: 91.95 | H255: =1-F255/G255 -> 0.4023926 | I255: 59.95 | J255: =ROUNDUP(I255/(1-H255),0)-0.05 -> 100.95 | K255: =I255-F255 -> 5 | L255: geen JR-herendata; proxy tank tops (dames) | M255: 16 | N255: 64.95 | O255: 69.95 | P255: =O255-I255 -> 10
A256: mens-long-sleeve-henley-knit-blend-button-neckline-relaxed-fit | B256: Men's Long Sleeve Henley | Knit Blend Button Neckline Relaxed Fit | C256: Shirts — T-shirts & polos | D256: Long Sleeve T-Shirt | E256: 42 | F256: 54.95 | G256: 109.95 | H256: =1-F256/G256 -> 0.50022738 | I256: 59.95 | J256: =ROUNDUP(I256/(1-H256),0)-0.05 -> 119.95 | K256: =I256-F256 -> 5 | L256: geen JR-herendata; proxy tank tops (dames) | M256: 16 | N256: 64.95 | O256: 69.95 | P256: =O256-I256 -> 10
A257: mens-long-sleeve-henley-raglan-crew-neck-knit | B257: Men's Long Sleeve Henley | Raglan Crew Neck Knit | C257: Shirts — T-shirts & polos | D257: Shirts | E257: 32 | F257: 54.95 | G257: 99.95 | H257: =1-F257/G257 -> 0.45022511 | I257: 59.95 | J257: =ROUNDUP(I257/(1-H257),0)-0.05 -> 109.95 | K257: =I257-F257 -> 5 | L257: geen JR-herendata; proxy tank tops (dames) | M257: 16 | N257: 64.95 | O257: 69.95 | P257: =O257-I257 -> 10
A258: mens-long-sleeve-shirt-crew-neck-knit-breathable | B258: Men's Long Sleeve Shirt | Crew Neck Knit Breathable | C258: Shirts — T-shirts & polos | D258: Clothing | E258: 35 | F258: 59.95 | G258: 109.95 | H258: =1-F258/G258 -> 0.45475216 | I258: 59.95 | J258: =ROUNDUP(I258/(1-H258),0)-0.05 -> 109.95 | K258: =I258-F258 -> 0 | L258: geen JR-herendata; proxy tank tops (dames) | M258: 16 | N258: 64.95 | O258: 69.95 | P258: =O258-I258 -> 10
A259: mens-no-sleeve-shirt-crew-neck-sleeveless-knit-athletic | B259: Men's No Sleeve Shirt | Crew Neck Sleeveless Knit Athletic | C259: Shirts — T-shirts & polos | D259: Men's Shirts | E259: 72 | F259: 59.95 | G259: 109.95 | H259: =1-F259/G259 -> 0.45475216 | I259: 59.95 | J259: =ROUNDUP(I259/(1-H259),0)-0.05 -> 109.95 | K259: =I259-F259 -> 0 | L259: geen JR-herendata; proxy tank tops (dames) | M259: 16 | N259: 64.95 | O259: 69.95 | P259: =O259-I259 -> 10
A260: mens-no-sleeve-shirt-henley-neckline-denim-pocket-sleeveless | B260: Men's No Sleeve Shirt | Henley Neckline Denim Pocket Sleeveless | C260: Shirts — T-shirts & polos | D260: T-Shirts & Tops | E260: 42 | F260: 59.95 | G260: 108.95 | H260: =1-F260/G260 -> 0.44974759 | I260: 59.95 | J260: =ROUNDUP(I260/(1-H260),0)-0.05 -> 108.95 | K260: =I260-F260 -> 0 | L260: geen JR-herendata; proxy tank tops (dames) | M260: 16 | N260: 64.95 | O260: 69.95 | P260: =O260-I260 -> 10
A261: mens-no-sleeve-shirt-henley-neckline-knit-sleeveless | B261: Men's No Sleeve Shirt | Henley Neckline Knit Sleeveless | C261: Shirts — T-shirts & polos | D261: T-Shirt | E261: 60 | F261: 59.95 | G261: 109.95 | H261: =1-F261/G261 -> 0.45475216 | I261: 59.95 | J261: =ROUNDUP(I261/(1-H261),0)-0.05 -> 109.95 | K261: =I261-F261 -> 0 | L261: geen JR-herendata; proxy tank tops (dames) | M261: 16 | N261: 64.95 | O261: 69.95 | P261: =O261-I261 -> 10
A262: mens-polo-top-collared-short-sleeve-button-pocket | B262: Men's Polo Top | Collared Short Sleeve Button Pocket | C262: Shirts — T-shirts & polos | D262: Shirts | E262: 36 | F262: 54.95 | G262: 109.95 | H262: =1-F262/G262 -> 0.50022738 | I262: 59.95 | J262: =ROUNDUP(I262/(1-H262),0)-0.05 -> 119.95 | K262: =I262-F262 -> 5 | L262: geen JR-herendata; proxy tank tops (dames) | M262: 16 | N262: 64.95 | O262: 69.95 | P262: =O262-I262 -> 10
A263: mens-polo-top-short-sleeve-knit-button-closure-v-neck | B263: Men's Polo Top | Short Sleeve Knit Button Closure V-Neck | C263: Shirts — T-shirts & polos | D263: Polo Shirts | E263: 42 | F263: 54.95 | G263: 109.95 | H263: =1-F263/G263 -> 0.50022738 | I263: 59.95 | J263: =ROUNDUP(I263/(1-H263),0)-0.05 -> 119.95 | K263: =I263-F263 -> 5 | L263: geen JR-herendata; proxy tank tops (dames) | M263: 16 | N263: 64.95 | O263: 69.95 | P263: =O263-I263 -> 10
A264: mens-polo-top-short-sleeve-knit-collared-button | B264: Men's Polo Top | Short Sleeve Knit Collared Button | C264: Shirts — T-shirts & polos | D264: Polo shirt | E264: 49 | F264: 54.95 | G264: 99.95 | H264: =1-F264/G264 -> 0.45022511 | I264: 59.95 | J264: =ROUNDUP(I264/(1-H264),0)-0.05 -> 109.95 | K264: =I264-F264 -> 5 | L264: geen JR-herendata; proxy tank tops (dames) | M264: 16 | N264: 64.95 | O264: 69.95 | P264: =O264-I264 -> 10
A265: mens-polo-top-short-sleeve-collar-knit-breathable | B265: Men's Polo Top | Short-Sleeve Collar Knit Breathable | C265: Shirts — T-shirts & polos | D265: Men Polo | E265: 63 | F265: 54.95 | G265: 109.95 | H265: =1-F265/G265 -> 0.50022738 | I265: 59.95 | J265: =ROUNDUP(I265/(1-H265),0)-0.05 -> 119.95 | K265: =I265-F265 -> 5 | L265: geen JR-herendata; proxy tank tops (dames) | M265: 16 | N265: 64.95 | O265: 69.95 | P265: =O265-I265 -> 10
...
