Workbook

Sheet Per categorie
A1: Lady Glam Boutique — prijsvoorstel per categorie (AUD)
A2: Bron: products export 23-10-2026 · 462 actieve producten · één prijs per product (alle varianten gelijk)
A4: Categorie | B4: Producten | C4: Huidig gem. | D4: Nieuw gem. | E4: Verschil % | F4: Nieuw laagste | G4: Nieuw hoogste | H4: Huidig laagste | I4: Huidig hoogste
A5: Tops & Blouses | B5: =COUNTIF('Per product'!$A$2:$A$463,A5) -> 56 | C5: =AVERAGEIF('Per product'!$A$2:$A$463,A5,'Per product'!$D$2:$D$463) -> 60.664286 | D5: =AVERAGEIF('Per product'!$A$2:$A$463,A5,'Per product'!$F$2:$F$463) -> 52.45 | E5: =IF(C5=0,0,D5/C5-1) -> -0.13540563 | F5: =_xlfn.MINIFS('Per product'!$F$2:$F$463,'Per product'!$A$2:$A$463,A5) -> 44.95 | G5: =_xlfn.MAXIFS('Per product'!$F$2:$F$463,'Per product'!$A$2:$A$463,A5) -> 54.95 | H5: =_xlfn.MINIFS('Per product'!$D$2:$D$463,'Per product'!$A$2:$A$463,A5) -> 44.95 | I5: =_xlfn.MAXIFS('Per product'!$D$2:$D$463,'Per product'!$A$2:$A$463,A5) -> 69.95
A6: Shorts | B6: =COUNTIF('Per product'!$A$2:$A$463,A6) -> 16 | C6: =AVERAGEIF('Per product'!$A$2:$A$463,A6,'Per product'!$D$2:$D$463) -> 60.575 | D6: =AVERAGEIF('Per product'!$A$2:$A$463,A6,'Per product'!$F$2:$F$463) -> 53.075 | E6: =IF(C6=0,0,D6/C6-1) -> -0.12381345 | F6: =_xlfn.MINIFS('Per product'!$F$2:$F$463,'Per product'!$A$2:$A$463,A6) -> 49.95 | G6: =_xlfn.MAXIFS('Per product'!$F$2:$F$463,'Per product'!$A$2:$A$463,A6) -> 54.95 | H6: =_xlfn.MINIFS('Per product'!$D$2:$D$463,'Per product'!$A$2:$A$463,A6) -> 49.95 | I6: =_xlfn.MAXIFS('Per product'!$D$2:$D$463,'Per product'!$A$2:$A$463,A6) -> 64.95
A7: Swimwear & Beachwear | B7: =COUNTIF('Per product'!$A$2:$A$463,A7) -> 32 | C7: =AVERAGEIF('Per product'!$A$2:$A$463,A7,'Per product'!$D$2:$D$463) -> 68.3875 | D7: =AVERAGEIF('Per product'!$A$2:$A$463,A7,'Per product'!$F$2:$F$463) -> 56.825 | E7: =IF(C7=0,0,D7/C7-1) -> -0.1690733 | F7: =_xlfn.MINIFS('Per product'!$F$2:$F$463,'Per product'!$A$2:$A$463,A7) -> 49.95 | G7: =_xlfn.MAXIFS('Per product'!$F$2:$F$463,'Per product'!$A$2:$A$463,A7) -> 64.95 | H7: =_xlfn.MINIFS('Per product'!$D$2:$D$463,'Per product'!$A$2:$A$463,A7) -> 49.95 | I7: =_xlfn.MAXIFS('Per product'!$D$2:$D$463,'Per product'!$A$2:$A$463,A7) -> 89.95
A8: Sandals & Slides | B8: =COUNTIF('Per product'!$A$2:$A$463,A8) -> 36 | C8: =AVERAGEIF('Per product'!$A$2:$A$463,A8,'Per product'!$D$2:$D$463) -> 74.533333 | D8: =AVERAGEIF('Per product'!$A$2:$A$463,A8,'Per product'!$F$2:$F$463) -> 59.811111 | E8: =IF(C8=0,0,D8/C8-1) -> -0.19752534 | F8: =_xlfn.MINIFS('Per product'!$F$2:$F$463,'Per product'!$A$2:$A$463,A8) -> 54.95 | G8: =_xlfn.MAXIFS('Per product'!$F$2:$F$463,'Per product'!$A$2:$A$463,A8) -> 64.95 | H8: =_xlfn.MINIFS('Per product'!$D$2:$D$463,'Per product'!$A$2:$A$463,A8) -> 54.95 | I8: =_xlfn.MAXIFS('Per product'!$D$2:$D$463,'Per product'!$A$2:$A$463,A8) -> 94.95
A9: Skirts | B9: =COUNTIF('Per product'!$A$2:$A$463,A9) -> 32 | C9: =AVERAGEIF('Per product'!$A$2:$A$463,A9,'Per product'!$D$2:$D$463) -> 74.6375 | D9: =AVERAGEIF('Per product'!$A$2:$A$463,A9,'Per product'!$F$2:$F$463) -> 62.7625 | E9: =IF(C9=0,0,D9/C9-1) -> -0.15910233 | F9: =_xlfn.MINIFS('Per product'!$F$2:$F$463,'Per product'!$A$2:$A$463,A9) -> 54.95 | G9: =_xlfn.MAXIFS('Per product'!$F$2:$F$463,'Per product'!$A$2:$A$463,A9) -> 64.95 | H9: =_xlfn.MINIFS('Per product'!$D$2:$D$463,'Per product'!$A$2:$A$463,A9) -> 54.95 | I9: =_xlfn.MAXIFS('Per product'!$D$2:$D$463,'Per product'!$A$2:$A$463,A9) -> 79.95
A10: Flats & Loafers | B10: =COUNTIF('Per product'!$A$2:$A$463,A10) -> 16 | C10: =AVERAGEIF('Per product'!$A$2:$A$463,A10,'Per product'!$D$2:$D$463) -> 79.6375 | D10: =AVERAGEIF('Per product'!$A$2:$A$463,A10,'Per product'!$F$2:$F$463) -> 63.3875 | E10: =IF(C10=0,0,D10/C10-1) -> -0.2040496 | F10: =_xlfn.MINIFS('Per product'!$F$2:$F$463,'Per product'!$A$2:$A$463,A10) -> 59.95 | G10: =_xlfn.MAXIFS('Per product'!$F$2:$F$463,'Per product'!$A$2:$A$463,A10) -> 69.95 | H10: =_xlfn.MINIFS('Per product'!$D$2:$D$463,'Per product'!$A$2:$A$463,A10) -> 64.95 | I10: =_xlfn.MAXIFS('Per product'!$D$2:$D$463,'Per product'!$A$2:$A$463,A10) -> 94.95
A11: Trousers & Pants | B11: =COUNTIF('Per product'!$A$2:$A$463,A11) -> 17 | C11: =AVERAGEIF('Per product'!$A$2:$A$463,A11,'Per product'!$D$2:$D$463) -> 72.008824 | D11: =AVERAGEIF('Per product'!$A$2:$A$463,A11,'Per product'!$F$2:$F$463) -> 64.067647 | E11: =IF(C11=0,0,D11/C11-1) -> -0.1102806 | F11: =_xlfn.MINIFS('Per product'!$F$2:$F$463,'Per product'!$A$2:$A$463,A11) -> 59.95 | G11: =_xlfn.MAXIFS('Per product'!$F$2:$F$463,'Per product'!$A$2:$A$463,A11) -> 69.95 | H11: =_xlfn.MINIFS('Per product'!$D$2:$D$463,'Per product'!$A$2:$A$463,A11) -> 64.95 | I11: =_xlfn.MAXIFS('Per product'!$D$2:$D$463,'Per product'!$A$2:$A$463,A11) -> 84.95
A12: Casual Dresses | B12: =COUNTIF('Per product'!$A$2:$A$463,A12) -> 102 | C12: =AVERAGEIF('Per product'!$A$2:$A$463,A12,'Per product'!$D$2:$D$463) -> 83.430392 | D12: =AVERAGEIF('Per product'!$A$2:$A$463,A12,'Per product'!$F$2:$F$463) -> 64.508824 | E12: =IF(C12=0,0,D12/C12-1) -> -0.22679467 | F12: =_xlfn.MINIFS('Per product'!$F$2:$F$463,'Per product'!$A$2:$A$463,A12) -> 59.95 | G12: =_xlfn.MAXIFS('Per product'!$F$2:$F$463,'Per product'!$A$2:$A$463,A12) -> 69.95 | H12: =_xlfn.MINIFS('Per product'!$D$2:$D$463,'Per product'!$A$2:$A$463,A12) -> 69.95 | I12: =_xlfn.MAXIFS('Per product'!$D$2:$D$463,'Per product'!$A$2:$A$463,A12) -> 99.95
A13: Jeans | B13: =COUNTIF('Per product'!$A$2:$A$463,A13) -> 10 | C13: =AVERAGEIF('Per product'!$A$2:$A$463,A13,'Per product'!$D$2:$D$463) -> 84.45 | D13: =AVERAGEIF('Per product'!$A$2:$A$463,A13,'Per product'!$F$2:$F$463) -> 70.45 | E13: =IF(C13=0,0,D13/C13-1) -> -0.16577857 | F13: =_xlfn.MINIFS('Per product'!$F$2:$F$463,'Per product'!$A$2:$A$463,A13) -> 64.95 | G13: =_xlfn.MAXIFS('Per product'!$F$2:$F$463,'Per product'!$A$2:$A$463,A13) -> 74.95 | H13: =_xlfn.MINIFS('Per product'!$D$2:$D$463,'Per product'!$A$2:$A$463,A13) -> 69.95 | I13: =_xlfn.MAXIFS('Per product'!$D$2:$D$463,'Per product'!$A$2:$A$463,A13) -> 94.95
A14: Formal & Occasion Dresses | B14: =COUNTIF('Per product'!$A$2:$A$463,A14) -> 57 | C14: =AVERAGEIF('Per product'!$A$2:$A$463,A14,'Per product'!$D$2:$D$463) -> 85.827193 | D14: =AVERAGEIF('Per product'!$A$2:$A$463,A14,'Per product'!$F$2:$F$463) -> 71.002632 | E14: =IF(C14=0,0,D14/C14-1) -> -0.17272569 | F14: =_xlfn.MINIFS('Per product'!$F$2:$F$463,'Per product'!$A$2:$A$463,A14) -> 64.95 | G14: =_xlfn.MAXIFS('Per product'!$F$2:$F$463,'Per product'!$A$2:$A$463,A14) -> 99.95 | H14: =_xlfn.MINIFS('Per product'!$D$2:$D$463,'Per product'!$A$2:$A$463,A14) -> 69.95 | I14: =_xlfn.MAXIFS('Per product'!$D$2:$D$463,'Per product'!$A$2:$A$463,A14) -> 99.95
A15: Heels | B15: =COUNTIF('Per product'!$A$2:$A$463,A15) -> 28 | C15: =AVERAGEIF('Per product'!$A$2:$A$463,A15,'Per product'!$D$2:$D$463) -> 87.45 | D15: =AVERAGEIF('Per product'!$A$2:$A$463,A15,'Per product'!$F$2:$F$463) -> 71.914286 | E15: =IF(C15=0,0,D15/C15-1) -> -0.17765254 | F15: =_xlfn.MINIFS('Per product'!$F$2:$F$463,'Per product'!$A$2:$A$463,A15) -> 64.95 | G15: =_xlfn.MAXIFS('Per product'!$F$2:$F$463,'Per product'!$A$2:$A$463,A15) -> 74.95 | H15: =_xlfn.MINIFS('Per product'!$D$2:$D$463,'Per product'!$A$2:$A$463,A15) -> 69.95 | I15: =_xlfn.MAXIFS('Per product'!$D$2:$D$463,'Per product'!$A$2:$A$463,A15) -> 94.95
A16: Jumpsuits & Playsuits | B16: =COUNTIF('Per product'!$A$2:$A$463,A16) -> 16 | C16: =AVERAGEIF('Per product'!$A$2:$A$463,A16,'Per product'!$D$2:$D$463) -> 90.575 | D16: =AVERAGEIF('Per product'!$A$2:$A$463,A16,'Per product'!$F$2:$F$463) -> 72.45 | E16: =IF(C16=0,0,D16/C16-1) -> -0.20011041 | F16: =_xlfn.MINIFS('Per product'!$F$2:$F$463,'Per product'!$A$2:$A$463,A16) -> 64.95 | G16: =_xlfn.MAXIFS('Per product'!$F$2:$F$463,'Per product'!$A$2:$A$463,A16) -> 74.95 | H16: =_xlfn.MINIFS('Per product'!$D$2:$D$463,'Per product'!$A$2:$A$463,A16) -> 79.95 | I16: =_xlfn.MAXIFS('Per product'!$D$2:$D$463,'Per product'!$A$2:$A$463,A16) -> 94.95
... A21: Boots | B21: =COUNTIF('Per product'!$A$2:$A$463,A21) -> 8 | C21: =AVERAGEIF('Per product'!$A$2:$A$463,A21,'Per product'!$D$2:$D$463) -> 107.45 | D21: =AVERAGEIF('Per product'!$A$2:$A$463,A21,'Per product'!$F$2:$F$463) -> 86.2 | E21: =IF(C21=0,0,D21/C21-1) -> -0.1977664 | F21: =_xlfn.MINIFS('Per product'!$F$2:$F$463,'Per product'!$A$2:$A$463,A21) -> 79.95 | G21: =_xlfn.MAXIFS('Per product'!$F$2:$F$463,'Per product'!$A$2:$A$463,A21) -> 89.95 | H21: =_xlfn.MINIFS('Per product'!$D$2:$D$463,'Per product'!$A$2:$A$463,A21) -> 94.95 | I21: =_xlfn.MAXIFS('Per product'!$D$2:$D$463,'Per product'!$A$2:$A$463,A21) -> 114.95
A22: Hele store | B22: =SUM(B5:B21) -> 462 | C22: =AVERAGE('Per product'!$D$2:$D$463) -> 79.051732 | D22: =AVERAGE('Per product'!$F$2:$F$463) -> 64.614502 | E22: =IF(C22=0,0,D22/C22-1) -> -0.18263015 | F22: =MIN('Per product'!$F$2:$F$463) -> 44.95 | G22: =MAX('Per product'!$F$2:$F$463) -> 99.95 | H22: =MIN('Per product'!$D$2:$D$463) -> 44.95 | I22: =MAX('Per product'!$D$2:$D$463) -> 114.95
A24: Regels voorstel:
A25: • Per categorie een nieuwe prijsband; binnen de band houdt elk product zijn plek (het duurste blijft het duurste). Afgerond op x4,95 / x9,95. Nooit omhoog.
A26: • Bestsellers 17–22 okt blijven op hun prijs: de 4 Capri Pants, Cocktail Dress Mini Fringe Feather (69,95) en Bandage Dress Maxi (99,95).
A27: • Compare-at: elk product houdt zijn eigen kortingspercentage (40/45/50%), opnieuw berekend en naar boven afgerond op hele dollars min 0,05 (ook de rare centen zoals 118,09 / 166,58 verdwijnen).
A28: • Nieuwe prijzen zijn blauw in 'Per product' — aanpassen kan daar, deze tab rekent mee.
A29: • Let op: 199 producten komen onder de oude LGB-bodem van A$64,95 (tops, shorts, swimwear, sandalen, rokken, casual dresses).

Sheet Per product
A1: Categorie | B1: Titel | C1: Handle | D1: Huidige prijs | E1: Huidige compare-at | F1: Nieuwe prijs | G1: Nieuwe compare-at | H1: Korting % | I1: Verschil (A$) | J1: Verschil % | K1: Opmerking
A2: Boots | B2: Women's Cowboy Boots | Cow Print Pointed Toe Block Heel | C2: womens-cowboy-boots-cow-print-pointed-toe-block-heel | D2: 99.95 | E2: 166.58 | F2: 79.95 | G2: 133.95 | H2: 0.4 | I2: =F2-D2 -> -20 | J2: =IF(D2=0,0,F2/D2-1) -> -0.20010005
A3: Boots | B3: Women's Platform Boots | Mid-Calf Square Heel Suede | C3: womens-platform-boots-mid-calf-square-heel-suede | D3: 94.95 | E3: 189.9 | F3: 79.95 | G3: 159.95 | H3: 0.5 | I3: =F3-D3 -> -15 | J3: =IF(D3=0,0,F3/D3-1) -> -0.15797788
A4: Boots | B4: Women's Slouch Boots | Mid-Calf Suede Buckle Detail Zipper | C4: womens-slouch-boots-mid-calf-suede-buckle-detail-zipper | D4: 99.95 | E4: 199.9 | F4: 79.95 | G4: 159.95 | H4: 0.5 | I4: =F4-D4 -> -20 | J4: =IF(D4=0,0,F4/D4-1) -> -0.20010005
A5: Boots | B5: Women's Cowboy Boots | Pointed Toe Leopard Print Block Heel | C5: womens-cowboy-boots-pointed-toe-leopard-print-block-heel | D5: 114.95 | E5: 229.9 | F5: 89.95 | G5: 179.95 | H5: 0.5 | I5: =F5-D5 -> -25 | J5: =IF(D5=0,0,F5/D5-1) -> -0.21748586
A6: Boots | B6: Women's Cowboy Boots | Round Toe Chunky Heel Leather Embroidered | C6: womens-cowboy-boots-round-toe-chunky-heel-leather-embroidered | D6: 114.95 | E6: 229.9 | F6: 89.95 | G6: 179.95 | H6: 0.5 | I6: =F6-D6 -> -25 | J6: =IF(D6=0,0,F6/D6-1) -> -0.21748586
A7: Boots | B7: Women's Platform Boots | Fur Cuff Suede Slip-On | C7: womens-platform-boots-fur-cuff-suede-slip-on | D7: 109.95 | E7: 219.9 | F7: 89.95 | G7: 179.95 | H7: 0.5 | I7: =F7-D7 -> -20 | J7: =IF(D7=0,0,F7/D7-1) -> -0.18190086
A8: Boots | B8: Women's Slouch Boots | Knee High Block Heel Buckle | C8: womens-slouch-boots-knee-high-block-heel-buckle | D8: 114.95 | E8: 191.58 | F8: 89.95 | G8: 149.95 | H8: 0.4 | I8: =F8-D8 -> -25 | J8: =IF(D8=0,0,F8/D8-1) -> -0.21748586
A9: Boots | B9: Women's Slouch Boots | Knee High Rounded Toe Low Heel | C9: womens-slouch-boots-knee-high-rounded-toe-low-heel | D9: 109.95 | E9: 183.25 | F9: 89.95 | G9: 149.95 | H9: 0.4 | I9: =F9-D9 -> -20 | J9: =IF(D9=0,0,F9/D9-1) -> -0.18190086
A10: Casual Dresses | B10: Women's Babydoll Dress | V-Neck Elbow Sleeve Midi Pockets | C10: womens-babydoll-dress-v-neck-elbow-sleeve-midi-pockets | D10: 69.95 | E10: 127.18 | F10: 59.95 | G10: 108.95 | H10: 0.45 | I10: =F10-D10 -> -10 | J10: =IF(D10=0,0,F10/D10-1) -> -0.14295926
A11: Casual Dresses | B11: Women's Beach Dress | V Neckline Wrap Tie Botanical Print | C11: womens-beach-dress-v-neckline-wrap-tie-botanical-print | D11: 69.95 | E11: 127.18 | F11: 59.95 | G11: 108.95 | H11: 0.45 | I11: =F11-D11 -> -10 | J11: =IF(D11=0,0,F11/D11-1) -> -0.14295926
A12: Casual Dresses | B12: Women's Boho Dress | V-Neck Puff Sleeve Midi Pockets | C12: womens-boho-dress-v-neck-puff-sleeve-midi-pockets | D12: 69.95 | E12: 116.58 | F12: 59.95 | G12: 99.95 | H12: 0.4 | I12: =F12-D12 -> -10 | J12: =IF(D12=0,0,F12/D12-1) -> -0.14295926
A13: Casual Dresses | B13: Women's Chiffon Dress | Maxi Length V-Neck Wrap Tiered Ruffles | C13: womens-chiffon-dress-maxi-length-v-neck-wrap-tiered-ruffles | D13: 69.95 | E13: 139.9 | F13: 59.95 | G13: 119.95 | H13: 0.5 | I13: =F13-D13 -> -10 | J13: =IF(D13=0,0,F13/D13-1) -> -0.14295926
... A144: Formal & Occasion Dresses | B144: Women's Cocktail Dress | Midi Length Keyhole Neckline Floral Print | C144: womens-cocktail-dress-midi-length-keyhole-neckline-floral-print | D144: 89.95 | E144: 163.55 | F144: 69.95 | G144: 127.95 | H144: 0.45 | I144: =F144-D144 -> -20 | J144: =IF(D144=0,0,F144/D144-1) -> -0.22234575
A145: Formal & Occasion Dresses | B145: Women's Cocktail Dress | Mini Fringe Feather Sleeveless V-Neck | C145: womens-cocktail-dress-mini-fringe-feather-sleeveless-v-neck | D145: 69.95 | E145: 116.58 | F145: 69.95 | G145: 116.95 | H145: 0.4 | I145: =F145-D145 -> 0 | J145: =IF(D145=0,0,F145/D145-1) -> 0 | K145: bestseller 17–22 okt — prijs blijft
A146: Formal & Occasion Dresses | B146: Women's Evening Dress | V-Neck Short Sleeve Sequin Midi | C146: womens-evening-dress-v-neck-short-sleeve-sequin-midi | D146: 84.95 | E146: 169.9 | F146: 69.95 | G146: 139.95 | H146: 0.5 | I146: =F146-D146 -> -15 | J146: =IF(D146=0,0,F146/D146-1) -> -0.17657446
A147: Formal & Occasion Dresses | B147: Women's Formal Dress | Maxi Strapless Choker Draped | C147: womens-formal-dress-maxi-strapless-choker-draped | D147: 84.95 | E147: 154.45 | F147: 69.95 | G147: 127.95 | H147: 0.45 | I147: =F147-D147 -> -15 | J147: =IF(D147=0,0,F147/D147-1) -> -0.17657446
A148: Formal & Occasion Dresses | B148: Women's Formal Dress | V-Neck Floral Maxi Wrapped | C148: womens-formal-dress-v-neck-floral-maxi-wrapped | D148: 84.95 | E148: 154.45 | F148: 69.95 | G148: 127.95 | H148: 0.45 | I148: =F148-D148 -> -15 | J148: =IF(D148=0,0,F148/D148-1) -> -0.17657446
A149: Formal & Occasion Dresses | B149: Women's Formal Dress | V-Neck Wraparound Floral Maxi | C149: womens-formal-dress-v-neck-wraparound-floral-maxi | D149: 84.95 | E149: 154.45 | F149: 69.95 | G149: 127.95 | H149: 0.45 | I149: =F149-D149 -> -15 | J149: =IF(D149=0,0,F149/D149-1) -> -0.17657446
A150: Formal & Occasion Dresses | B150: Women's Lace Dress | V-Neck Floral Long Sleeve | C150: womens-lace-dress-v-neck-floral-long-sleeve | D150: 79.95 | E150: 145.36 | F150: 69.95 | G150: 127.95 | H150: 0.45 | I150: =F150-D150 -> -10 | J150: =IF(D150=0,0,F150/D150-1) -> -0.12507817
A151: Formal & Occasion Dresses | B151: Women's Lace Dress | V-Neck Midi Knit Lace Sleeves | C151: womens-lace-dress-v-neck-midi-knit-lace-sleeves | D151: 84.95 | E151: 141.58 | F151: 69.95 | G151: 116.95 | H151: 0.4 | I151: =F151-D151 -> -15 | J151: =IF(D151=0,0,F151/D151-1) -> -0.17657446
A152: Formal & Occasion Dresses | B152: Women's Lace Dress | V-Neck Sleeveless Midi Lace Trim | C152: womens-lace-dress-v-neck-sleeveless-midi-lace-trim | D152: 84.95 | E152: 141.58 | F152: 69.95 | G152: 116.95 | H152: 0.4 | I152: =F152-D152 -> -15 | J152: =IF(D152=0,0,F152/D152-1) -> -0.17657446
A153: Formal & Occasion Dresses | B153: Women's Lace Maxi Dress | Strapless Ruched Bodice Sheer Overlay | C153: womens-lace-maxi-dress-strapless-ruched-bodice-sheer-overlay | D153: 84.95 | E153: 169.9 | F153: 69.95 | G153: 139.95 | H153: 0.5 | I153: =F153-D153 -> -15 | J153: =IF(D153=0,0,F153/D153-1) -> -0.17657446
A154: Formal & Occasion Dresses | B154: Women's Lace Mini Dress | V-Neck Three-Quarter Sleeve Crochet | C154: womens-lace-mini-dress-v-neck-three-quarter-sleeve-crochet | D154: 84.95 | E154: 141.58 | F154: 69.95 | G154: 116.95 | H154: 0.4 | I154: =F154-D154 -> -15 | J154: =IF(D154=0,0,F154/D154-1) -> -0.17657446
A155: Formal & Occasion Dresses | B155: Women's Midi Elegant Dress | Round Neckline Short Sleeve Tiered | C155: womens-midi-elegant-dress-round-neckline-short-sleeve-tiered | D155: 79.95 | E155: 159.9 | F155: 69.95 | G155: 139.95 | H155: 0.5 | I155: =F155-D155 -> -10 | J155: =IF(D155=0,0,F155/D155-1) -> -0.12507817
A156: Formal & Occasion Dresses | B156: Women's Mini Cocktail Dress | V Neckline Long Sleeves Ribbed Knit | C156: womens-mini-cocktail-dress-v-neckline-long-sleeves-ribbed-knit | D156: 79.95 | E156: 145.36 | F156: 69.95 | G156: 127.95 | H156: 0.45 | I156: =F156-D156 -> -10 | J156: =IF(D156=0,0,F156/D156-1) -> -0.12507817
A157: Formal & Occasion Dresses | B157: Women's Mini Cocktail Dress | V-Neck Flutter Sleeve Lace Trim Zipper | C157: womens-mini-cocktail-dress-v-neck-flutter-sleeve-lace-trim-zipper | D157: 84.95 | E157: 141.58 | F157: 69.95 | G157: 116.95 | H157: 0.4 | I157: =F157-D157 -> -15 | J157: =IF(D157=0,0,F157/D157-1) -> -0.17657446
... A183: Formal & Occasion Dresses | B183: Women's Silk Dress | Midi Length V-Neck Short Sleeve Pleated | C183: womens-silk-dress-midi-length-v-neck-short-sleeve-pleated | D183: 99.95 | E183: 166.58 | F183: 74.95 | G183: 124.95 | H183: 0.4 | I183: =F183-D183 -> -25 | J183: =IF(D183=0,0,F183/D183-1) -> -0.25012506
A184: Formal & Occasion Dresses | B184: Women's Bandage Dress | Maxi Scoop Neckline Sleeveless Stretch | C184: womens-bandage-dress-maxi-scoop-neckline-sleeveless-stretch | D184: 99.95 | E184: 166.58 | F184: 99.95 | G184: 166.95 | H184: 0.4 | I184: =F184-D184 -> 0 | J184: =IF(D184=0,0,F184/D184-1) -> 0 | K184: bestseller 17–22 okt — prijs blijft
A185: Heels | B185: Women's High Heels | Open Toe T-Strap Peep Suede | C185: womens-high-heels-open-toe-t-strap-peep-suede | D185: 69.95 | E185: 116.58 | F185: 64.95 | G185: 108.95 | H185: 0.4 | I185: =F185-D185 -> -5 | J185: =IF(D185=0,0,F185/D185-1) -> -0.071479628
A186: Heels | B186: Women's Kitten Heels | Open-Toe Knotted Square-Toe Slip-On | C186: womens-kitten-heels-open-toe-knotted-square-toe-slip-on | D186: 69.95 | E186: 116.58 | F186: 64.95 | G186: 108.95 | H186: 0.4 | I186: =F186-D186 -> -5 | J186: =IF(D186=0,0,F186/D186-1) -> -0.071479628
A187: Heels | B187: Women's Mules | Embroidered Floral Canvas Slip-On | C187: womens-mules-embroidered-floral-canvas-slip-on | D187: 69.95 | E187: 127.18 | F187: 64.95 | G187: 118.95 | H187: 0.45 | I187: =F187-D187 -> -5 | J187: =IF(D187=0,0,F187/D187-1) -> -0.071479628
A188: Heels | B188: Women's Mules | Pointed Toe Buckle Strap Heel | C188: womens-mules-pointed-toe-buckle-strap-heel | D188: 69.95 | E188: 127.18 | F188: 64.95 | G188: 118.95 | H188: 0.45 | I188: =F188-D188 -> -5 | J188: =IF(D188=0,0,F188/D188-1) -> -0.071479628
A189: Heels | B189: Women's Thong Heels | Open Toe Block Heel Slip On | C189: womens-thong-heels-open-toe-block-heel-slip-on | D189: 74.95 | E189: 124.92 | F189: 64.95 | G189: 108.95 | H189: 0.4 | I189: =F189-D189 -> -10 | J189: =IF(D189=0,0,F189/D189-1) -> -0.13342228
A190: Heels | B190: Women's Block Heels | Braided Toe Ankle Strap Buckle Platform | C190: womens-block-heels-braided-toe-ankle-strap-buckle-platform | D190: 79.95 | E190: 159.9 | F190: 69.95 | G190: 139.95 | H190: 0.5 | I190: =F190-D190 -> -10 | J190: =IF(D190=0,0,F190/D190-1) -> -0.12507817
A191: Heels | B191: Women's High Heels | Suede Buckle Closure Block Heel Square Toe | C191: womens-high-heels-suede-buckle-closure-block-heel-square-toe | D191: 79.95 | E191: 159.9 | F191: 69.95 | G191: 139.95 | H191: 0.5 | I191: =F191-D191 -> -10 | J191: =IF(D191=0,0,F191/D191-1) -> -0.12507817
A192: Heels | B192: Women's Mules | Hollow-Out Design Bow Closure Flat Sole | C192: womens-mules-hollow-out-design-bow-closure-flat-sole | D192: 84.95 | E192: 154.45 | F192: 69.95 | G192: 127.95 | H192: 0.45 | I192: =F192-D192 -> -15 | J192: =IF(D192=0,0,F192/D192-1) -> -0.17657446
A193: Heels | B193: Women's Mules | Hollow-Out Design Flat Bow Closure | C193: womens-mules-hollow-out-design-flat-bow-closure | D193: 84.95 | E193: 154.45 | F193: 69.95 | G193: 127.95 | H193: 0.45 | I193: =F193-D193 -> -15 | J193: =IF(D193=0,0,F193/D193-1) -> -0.17657446
A194: Heels | B194: Women's Mules | Pointed Toe Mary Jane Leather | C194: womens-mules-pointed-toe-mary-jane-strap-leather | D194: 84.95 | E194: 169.9 | F194: 69.95 | G194: 139.95 | H194: 0.5 | I194: =F194-D194 -> -15 | J194: =IF(D194=0,0,F194/D194-1) -> -0.17657446
A195: Heels | B195: Women's Mules | Pointed Toe Mary Jane Strap Leather | C195: womens-mules-pointed-toe-mary-jane-strap-leather-1 | D195: 84.95 | E195: 141.58 | F195: 69.95 | G195: 116.95 | H195: 0.4 | I195: =F195-D195 -> -15 | J195: =IF(D195=0,0,F195/D195-1) -> -0.17657446
...
