Workbook

Sheet Overzicht
A1: Prijzen onder $45 — productexport
A2: Bron: products_export_1.csv (Shopify-export, vendor Emily Neill): 879 producten, 27.469 varianten met prijs
A4: Producten totaal in de export | B4: 879
A5: Producten met een prijs onder $45 | B5: =COUNTA('Onder 45 dollar'!A2:A227) -> 226
A6: Varianten onder $45 | B6: 7961
A7: Laagste prijs | B7: =MIN('Onder 45 dollar'!D2:D227) -> 27.95
A8: Hoogste prijs onder de grens | B8: =MAX('Onder 45 dollar'!D2:D227) -> 44.95
A9: Gemiddelde prijs onder $45 | B9: =AVERAGE('Onder 45 dollar'!D2:D227) -> 40.480973
A10: Gemiddelde korting t.o.v. compare-at | B10: =AVERAGE('Onder 45 dollar'!F2:F227) -> 0.50067746
A12: Per prijspunt
A13: Prijs | B13: Producten | C13: Categorieën (top 3)
A14: 27.95 | B14: =COUNTIF('Onder 45 dollar'!$D$2:$D$227,A14) -> 1 | C14: swimwear (1)
A15: 28.95 | B15: =COUNTIF('Onder 45 dollar'!$D$2:$D$227,A15) -> 2 | C15: sandals (1), skirts (1)
A16: 29.95 | B16: =COUNTIF('Onder 45 dollar'!$D$2:$D$227,A16) -> 9 | C16: tanktops (3), trousers (2), leggings (2)
A17: 31.95 | B17: =COUNTIF('Onder 45 dollar'!$D$2:$D$227,A17) -> 1 | C17: shorts (1)
A18: 32.95 | B18: =COUNTIF('Onder 45 dollar'!$D$2:$D$227,A18) -> 1 | C18: shoes (1)
A19: 33.95 | B19: =COUNTIF('Onder 45 dollar'!$D$2:$D$227,A19) -> 1 | C19: shorts (1)
A20: 34.95 | B20: =COUNTIF('Onder 45 dollar'!$D$2:$D$227,A20) -> 31 | C20: tanktops (8), swimwear (6), graduation (3)
A21: 35.95 | B21: =COUNTIF('Onder 45 dollar'!$D$2:$D$227,A21) -> 4 | C21: sandals (2), jackets (1), blouses (1)
A22: 36.95 | B22: =COUNTIF('Onder 45 dollar'!$D$2:$D$227,A22) -> 2 | C22: formaldress (1), hoodies (1)
A23: 37.95 | B23: =COUNTIF('Onder 45 dollar'!$D$2:$D$227,A23) -> 4 | C23: blouses (2), casualdress (1), shorts (1)
A24: 38.95 | B24: =COUNTIF('Onder 45 dollar'!$D$2:$D$227,A24) -> 4 | C24: sandals (1), shorts (1), swimwear (1)
A25: 39.95 | B25: =COUNTIF('Onder 45 dollar'!$D$2:$D$227,A25) -> 57 | C25: tanktops (9), casualdress (7), swimwear (7)
... A30: 44.95 | B30: =COUNTIF('Onder 45 dollar'!$D$2:$D$227,A30) -> 72 | C30: casualdress (15), shoes (10), sandals (9)
A31: Totaal | B31: =SUM(B14:B30) -> 226
A33: Per categorie
A34: Categorie | B34: Producten | C34: Laagste prijs
A35: casualdress | B35: =COUNTIF('Onder 45 dollar'!$C$2:$C$227,A35) -> 29 | C35: =_xlfn.MINIFS('Onder 45 dollar'!$D$2:$D$227,'Onder 45 dollar'!$C$2:$C$227,A35) -> 34.95
A36: tanktops | B36: =COUNTIF('Onder 45 dollar'!$C$2:$C$227,A36) -> 27 | C36: =_xlfn.MINIFS('Onder 45 dollar'!$D$2:$D$227,'Onder 45 dollar'!$C$2:$C$227,A36) -> 29.95
A37: sandals | B37: =COUNTIF('Onder 45 dollar'!$C$2:$C$227,A37) -> 24 | C37: =_xlfn.MINIFS('Onder 45 dollar'!$D$2:$D$227,'Onder 45 dollar'!$C$2:$C$227,A37) -> 28.95
A38: swimwear | B38: =COUNTIF('Onder 45 dollar'!$C$2:$C$227,A38) -> 23 | C38: =_xlfn.MINIFS('Onder 45 dollar'!$D$2:$D$227,'Onder 45 dollar'!$C$2:$C$227,A38) -> 27.95
A39: shoes | B39: =COUNTIF('Onder 45 dollar'!$C$2:$C$227,A39) -> 18 | C39: =_xlfn.MINIFS('Onder 45 dollar'!$D$2:$D$227,'Onder 45 dollar'!$C$2:$C$227,A39) -> 32.95
A40: blouses | B40: =COUNTIF('Onder 45 dollar'!$C$2:$C$227,A40) -> 13 | C40: =_xlfn.MINIFS('Onder 45 dollar'!$D$2:$D$227,'Onder 45 dollar'!$C$2:$C$227,A40) -> 35.95
A41: trousers | B41: =COUNTIF('Onder 45 dollar'!$C$2:$C$227,A41) -> 12 | C41: =_xlfn.MINIFS('Onder 45 dollar'!$D$2:$D$227,'Onder 45 dollar'!$C$2:$C$227,A41) -> 29.95
A42: shorts | B42: =COUNTIF('Onder 45 dollar'!$C$2:$C$227,A42) -> 12 | C42: =_xlfn.MINIFS('Onder 45 dollar'!$D$2:$D$227,'Onder 45 dollar'!$C$2:$C$227,A42) -> 29.95
A43: leggings | B43: =COUNTIF('Onder 45 dollar'!$C$2:$C$227,A43) -> 11 | C43: =_xlfn.MINIFS('Onder 45 dollar'!$D$2:$D$227,'Onder 45 dollar'!$C$2:$C$227,A43) -> 29.95
A44: hoodies | B44: =COUNTIF('Onder 45 dollar'!$C$2:$C$227,A44) -> 10 | C44: =_xlfn.MINIFS('Onder 45 dollar'!$D$2:$D$227,'Onder 45 dollar'!$C$2:$C$227,A44) -> 34.95
A45: skirts | B45: =COUNTIF('Onder 45 dollar'!$C$2:$C$227,A45) -> 8 | C45: =_xlfn.MINIFS('Onder 45 dollar'!$D$2:$D$227,'Onder 45 dollar'!$C$2:$C$227,A45) -> 28.95
A46: weddingguest | B46: =COUNTIF('Onder 45 dollar'!$C$2:$C$227,A46) -> 8 | C46: =_xlfn.MINIFS('Onder 45 dollar'!$D$2:$D$227,'Onder 45 dollar'!$C$2:$C$227,A46) -> 29.95
... A54: menssweaters | B54: =COUNTIF('Onder 45 dollar'!$C$2:$C$227,A54) -> 1 | C54: =_xlfn.MINIFS('Onder 45 dollar'!$D$2:$D$227,'Onder 45 dollar'!$C$2:$C$227,A54) -> 44.95
...

Sheet Onder 45 dollar
A1: Handle | B1: Titel | C1: Categorie | D1: Prijs | E1: Compare at | F1: Korting % | G1: Varianten | H1: Alle varianten < $45
A2: womens-one-piece-swimsuit-halter-neck-wrap-style | B2: Women's One Piece Swimsuit | Halter Neck Wrap Style | C2: swimwear | D2: 27.95 | E2: 56 | F2: =IFERROR(1-D2/E2,"") -> 0.50089286 | G2: 50 | H2: ja
A3: sandals-for-women-lace-up-block-heel-open-toe | B3: Sandals For Women | Lace Up Block Heel Open Toe | C3: sandals | D3: 28.95 | E3: 58 | F3: =IFERROR(1-D3/E3,"") -> 0.50086207 | G3: 34 | H3: ja
A4: womens-skirt-midi-leopard-print-wrap-high-slit | B4: Women's Skirt | Midi Leopard Print Wrap High Slit | C4: skirts | D4: 28.95 | E4: 58 | F4: =IFERROR(1-D4/E4,"") -> 0.50086207 | G4: 4 | H4: ja
A5: womens-cargo-pants-wide-leg-drawstring-street-style | B5: Women's Cargo Pants | Wide Leg Drawstring Street Style | C5: trousers | D5: 29.95 | E5: 60 | F5: =IFERROR(1-D5/E5,"") -> 0.50083333 | G5: 35 | H5: ja
A6: womens-halter-top-deep-v-neck-ribbed | B6: Women's Halter Top | Deep V-Neck Ribbed | C6: tanktops | D6: 29.95 | E6: 60 | F6: =IFERROR(1-D6/E6,"") -> 0.50083333 | G6: 5 | H6: ja
A7: womens-halter-top-lace-trim-asymmetric-sleeveless-black | B7: Women's Halter Top | Lace Trim Asymmetric Sleeveless Black | C7: tanktops | D7: 29.95 | E7: 60 | F7: =IFERROR(1-D7/E7,"") -> 0.50083333 | G7: 4 | H7: ja
A8: womens-halter-top-plunging-neck-back-tie-sleeveless | B8: Women's Halter Top | Plunging Neck Back Tie Sleeveless | C8: tanktops | D8: 29.95 | E8: 60 | F8: =IFERROR(1-D8/E8,"") -> 0.50083333 | G8: 9 | H8: ja
A9: womens-leggings-fleece-lined-high-waisted | B9: Women's Leggings | Fleece Lined High Waisted | C9: leggings | D9: 29.95 | E9: 60 | F9: =IFERROR(1-D9/E9,"") -> 0.50083333 | G9: 20 | H9: ja
A10: womens-leggings-tummy-control-butt-lift | B10: Women's Leggings | Tummy Control Butt Lift | C10: leggings | D10: 29.95 | E10: 60 | F10: =IFERROR(1-D10/E10,"") -> 0.50083333 | G10: 18 | H10: ja
A11: womens-linen-pants-drawstring-elastic-waist | B11: Women's Linen Pants | Drawstring Elastic Waist | C11: trousers | D11: 29.95 | E11: 60 | F11: =IFERROR(1-D11/E11,"") -> 0.50083333 | G11: 35 | H11: ja
A12: womens-shorts-high-waist-belted-pleated | B12: Women's Shorts | High Waist Belted Pleated | C12: shorts | D12: 29.95 | E12: 60 | F12: =IFERROR(1-D12/E12,"") -> 0.50083333 | G12: 14 | H12: ja
A13: womens-wedding-guest-dress-maxi-pleated-halter-neck | B13: Women's Wedding Guest Dress | Maxi Pleated Halter Neck | C13: weddingguest | D13: 29.95 | E13: 60 | F13: =IFERROR(1-D13/E13,"") -> 0.50083333 | G13: 8 | H13: ja
... A227: womens-white-dress-midi-wrap-v-neck-belted | B227: Women's White Dress | Midi Wrap V-Neck Belted | C227: casualdress | D227: 44.95 | E227: 90 | F227: =IFERROR(1-D227/E227,"") -> 0.50055556 | G227: 5 | H227: ja
