Workbook

Sheet Overzicht
A1: Prijsvoorstel — alles onder $50 omhoog
A2: Bron: products_export_1.csv · 879 producten in de store · 352 producten (12.118 varianten) staan nu onder $50
A4: Producten in dit voorstel | B4: =COUNTA(Prijsvoorstel!A2:A353) -> 352
A5: Waarvan geen stijging nodig | B5: =COUNTIF(Prijsvoorstel!K2:K353,0) -> 19
A6: Laagste prijs nu | B6: =MIN(Prijsvoorstel!E2:E353) -> 27.95
A7: Laagste prijs na aanpassing | B7: =MIN(Prijsvoorstel!H2:H353) -> 49.95
A8: Gemiddelde stijging | B8: =AVERAGE(Prijsvoorstel!K2:K353) -> 14.130682
A9: Gemiddelde stijging in % | B9: =AVERAGE(Prijsvoorstel!L2:L353) -> 0.34455491
A10: Korting was gemiddeld | B10: =AVERAGE(Prijsvoorstel!G2:G353) -> 0.49596549
A11: Korting blijft gemiddeld | B11: =AVERAGE(Prijsvoorstel!J2:J353) -> 0.49996544
A13: Nieuwe prijspunten
A14: Prijsgroep | B14: Nieuwe prijs | C14: Nieuwe compare | D14: Producten
A15: basis | B15: 49.95 | C15: 100 | D15: =COUNTIF(Prijsvoorstel!$H$2:$H$353,B15) -> 127
A16: midden | B16: 59.95 | C16: 120 | D16: =COUNTIF(Prijsvoorstel!$H$2:$H$353,B16) -> 176
A17: premium | B17: 69.95 | C17: 140 | D17: =COUNTIF(Prijsvoorstel!$H$2:$H$353,B17) -> 49
A18: Totaal | D18: =SUM(D15:D17) -> 352
A20: Per categorie
A21: Categorie | B21: Producten | C21: Mediaan nu | D21: Mediaan nieuw
A22: blouses | B22: =COUNTIF(Prijsvoorstel!$C$2:$C$353,A22) -> 26 | C22: 45.45 | D22: 49.95
A23: boots | B23: =COUNTIF(Prijsvoorstel!$C$2:$C$353,A23) -> 5 | C23: 42.95 | D23: 69.95
A24: casualdress | B24: =COUNTIF(Prijsvoorstel!$C$2:$C$353,A24) -> 52 | C24: 44.95 | D24: 59.95
A25: formaldress | B25: =COUNTIF(Prijsvoorstel!$C$2:$C$353,A25) -> 8 | C25: 39.95 | D25: 69.95
A26: graduation | B26: =COUNTIF(Prijsvoorstel!$C$2:$C$353,A26) -> 6 | C26: 39.95 | D26: 59.95
A27: hoodies | B27: =COUNTIF(Prijsvoorstel!$C$2:$C$353,A27) -> 16 | C27: 42.95 | D27: 59.95
A28: jackets | B28: =COUNTIF(Prijsvoorstel!$C$2:$C$353,A28) -> 10 | C28: 49.95 | D28: 69.95
A29: jeans | B29: =COUNTIF(Prijsvoorstel!$C$2:$C$353,A29) -> 12 | C29: 49.45 | D29: 59.95
A30: leggings | B30: =COUNTIF(Prijsvoorstel!$C$2:$C$353,A30) -> 11 | C30: 39.95 | D30: 49.95
A31: menssandals | B31: =COUNTIF(Prijsvoorstel!$C$2:$C$353,A31) -> 1 | C31: 47.95 | D31: 59.95
A32: mensshoes | B32: =COUNTIF(Prijsvoorstel!$C$2:$C$353,A32) -> 4 | C32: 42.45 | D32: 69.95
A33: mensshorts | B33: =COUNTIF(Prijsvoorstel!$C$2:$C$353,A33) -> 4 | C33: 46.45 | D33: 49.95
... A44: weddingguest | B44: =COUNTIF(Prijsvoorstel!$C$2:$C$353,A44) -> 15 | C44: 44.95 | D44: 69.95
A47: Methode
A48: Basis $49,95 — tops, tanktops, blouses, rokken, shorts, leggings, swimwear, heren shorts.
A49: Midden $59,95 — jurken (ook shirt dresses), broeken, jeans, hoodies en sweatshirts, sandalen, schoenen, graduation.
A50: Premium $69,95 — wedding guest en formal dresses, cocktail, jassen en blazers, boots, sweaters, heren schoenen en loafers.
A51: Kolom Prijsgroep laat zien in welke groep een product valt; de groep komt van de tag, met de titel als correctie (een shirt dress met tag blouses gaat naar midden).
A52: Alle nieuwe prijzen eindigen op 4,95 of 9,95 en gaan alleen omhoog, nooit omlaag.
A53: Compare-at schaalt mee met dezelfde verhouding als nu (vrijwel overal 2x), afgerond op een heel bedrag, dus het kortingspercentage blijft gelijk.
A54: Vier producten zijn geel gemarkeerd in het tabblad Prijsvoorstel: daar staat de compare-at nu fout of afwijkend in de export.

Sheet Prijsvoorstel
A1: Handle | B1: Titel | C1: Categorie | D1: Prijsgroep | E1: Prijs nu | F1: Compare nu | G1: Korting nu | H1: Nieuwe prijs | I1: Nieuwe compare | J1: Nieuwe korting | K1: Stijging $ | L1: Stijging % | M1: Varianten | N1: Opmerking
A2: womens-blouse-boho-floral-print-button-front | B2: Women's Blouse | Boho Floral Print Button Front | C2: blouses | D2: basis | E2: 39.95 | F2: 80 | G2: =IFERROR(1-E2/F2,"") -> 0.500625 | H2: 49.95 | I2: =ROUND(H2*F2/E2,0) -> 100 | J2: =IFERROR(1-H2/I2,"") -> 0.5005 | K2: =H2-E2 -> 10 | L2: =IFERROR(H2/E2-1,"") -> 0.25031289 | M2: 40
A3: womens-linen-shirt-floral-button-front-long-sleeve-blouse | B3: Women's Linen Shirt | Floral Button Front Long Sleeve Blouse | C3: blouses | D3: basis | E3: 39.95 | F3: 80 | G3: =IFERROR(1-E3/F3,"") -> 0.500625 | H3: 49.95 | I3: =ROUND(H3*F3/E3,0) -> 100 | J3: =IFERROR(1-H3/I3,"") -> 0.5005 | K3: =H3-E3 -> 10 | L3: =IFERROR(H3/E3-1,"") -> 0.25031289 | M3: 54
A4: womens-linen-shirt-short-sleeve-button-down | B4: Women's Linen Shirt | Short Sleeve Button Down | C4: blouses | D4: basis | E4: 39.95 | F4: 80 | G4: =IFERROR(1-E4/F4,"") -> 0.500625 | H4: 49.95 | I4: =ROUND(H4*F4/E4,0) -> 100 | J4: =IFERROR(1-H4/I4,"") -> 0.5005 | K4: =H4-E4 -> 10 | L4: =IFERROR(H4/E4-1,"") -> 0.25031289 | M4: 88
A5: womens-shirt-long-sleeve-button-front | B5: Women's Shirt | Long Sleeve Button Front | C5: blouses | D5: basis | E5: 39.95 | F5: 80 | G5: =IFERROR(1-E5/F5,"") -> 0.500625 | H5: 49.95 | I5: =ROUND(H5*F5/E5,0) -> 100 | J5: =IFERROR(1-H5/I5,"") -> 0.5005 | K5: =H5-E5 -> 10 | L5: =IFERROR(H5/E5-1,"") -> 0.25031289 | M5: 24
A6: womens-blouse-floral-eyelet-short-sleeve-button-front | B6: Women's Blouse | Floral Eyelet Short Sleeve Button Front | C6: blouses | D6: basis | E6: 44.95 | F6: 90 | G6: =IFERROR(1-E6/F6,"") -> 0.50055556 | H6: 49.95 | I6: =ROUND(H6*F6/E6,0) -> 100 | J6: =IFERROR(1-H6/I6,"") -> 0.5005 | K6: =H6-E6 -> 5 | L6: =IFERROR(H6/E6-1,"") -> 0.11123471 | M6: 72
A7: womens-shirt-zebra-print-long-sleeve-button-down | B7: Women's Shirt | Zebra Print Long Sleeve Button Down | C7: blouses | D7: basis | E7: 45.95 | F7: 92 | G7: =IFERROR(1-E7/F7,"") -> 0.50054348 | H7: 49.95 | I7: =ROUND(H7*F7/E7,0) -> 100 | J7: =IFERROR(1-H7/I7,"") -> 0.5005 | K7: =H7-E7 -> 4 | L7: =IFERROR(H7/E7-1,"") -> 0.087051143 | M7: 10
A8: womens-blouse-button-front-long-sleeve | B8: Women's Blouse | Button Front Long Sleeve | C8: blouses | D8: basis | E8: 49.95 | F8: 100 | G8: =IFERROR(1-E8/F8,"") -> 0.5005 | H8: 49.95 | I8: =ROUND(H8*F8/E8,0) -> 100 | J8: =IFERROR(1-H8/I8,"") -> 0.5005 | K8: =H8-E8 -> 0 | L8: =IFERROR(H8/E8-1,"") -> 0 | M8: 40
A9: womens-blouse-floral-embroidered-sheer-sleeve-button-front | B9: Women's Blouse | Floral Embroidered Sheer Sleeve Button Front | C9: blouses | D9: basis | E9: 49.95 | F9: 100 | G9: =IFERROR(1-E9/F9,"") -> 0.5005 | H9: 49.95 | I9: =ROUND(H9*F9/E9,0) -> 100 | J9: =IFERROR(1-H9/I9,"") -> 0.5005 | K9: =H9-E9 -> 0 | L9: =IFERROR(H9/E9-1,"") -> 0 | M9: 16
A10: womens-blouse-floral-print-v-neck-short-sleeve | B10: Women's Blouse | Floral Print V-Neck Short Sleeve | C10: blouses | D10: basis | E10: 49.95 | F10: 100 | G10: =IFERROR(1-E10/F10,"") -> 0.5005 | H10: 49.95 | I10: =ROUND(H10*F10/E10,0) -> 100 | J10: =IFERROR(1-H10/I10,"") -> 0.5005 | K10: =H10-E10 -> 0 | L10: =IFERROR(H10/E10-1,"") -> 0 | M10: 8
A11: womens-blouse-long-sleeve-v-neck | B11: Women's Blouse | Long Sleeve V-Neck | C11: blouses | D11: basis | E11: 49.95 | F11: 100 | G11: =IFERROR(1-E11/F11,"") -> 0.5005 | H11: 49.95 | I11: =ROUND(H11*F11/E11,0) -> 100 | J11: =IFERROR(1-H11/I11,"") -> 0.5005 | K11: =H11-E11 -> 0 | L11: =IFERROR(H11/E11-1,"") -> 0 | M11: 8
A12: womens-blouse-polka-dot-color-block-v-neck-short-sleeve | B12: Women's Blouse | Polka Dot Color Block V-Neck Short Sleeve | C12: blouses | D12: basis | E12: 49.95 | F12: 100 | G12: =IFERROR(1-E12/F12,"") -> 0.5005 | H12: 49.95 | I12: =ROUND(H12*F12/E12,0) -> 100 | J12: =IFERROR(1-H12/I12,"") -> 0.5005 | K12: =H12-E12 -> 0 | L12: =IFERROR(H12/E12-1,"") -> 0 | M12: 8
A13: womens-blouse-summer-beach-cover-up-short-sleeve | B13: Women's Blouse | Summer Beach Cover Up Short Sleeve | C13: blouses | D13: basis | E13: 49.95 | F13: 100 | G13: =IFERROR(1-E13/F13,"") -> 0.5005 | H13: 49.95 | I13: =ROUND(H13*F13/E13,0) -> 100 | J13: =IFERROR(1-H13/I13,"") -> 0.5005 | K13: =H13-E13 -> 0 | L13: =IFERROR(H13/E13-1,"") -> 0 | M13: 56
... A23: womens-leggings-skinny-pu-leather-bowknot | B23: Women's Leggings | Skinny PU Leather Bowknot | C23: leggings | D23: basis | E23: 39.95 | F23: 80 | G23: =IFERROR(1-E23/F23,"") -> 0.500625 | H23: 49.95 | I23: =ROUND(H23*F23/E23,0) -> 100 | J23: =IFERROR(1-H23/I23,"") -> 0.5005 | K23: =H23-E23 -> 10 | L23: =IFERROR(H23/E23-1,"") -> 0.25031289 | M23: 12
A24: womens-leggings-stirrup-high-waist-black | B24: Women's Leggings | Stirrup High Waist Black | C24: leggings | D24: basis | E24: 39.95 | F24: 60 | G24: =IFERROR(1-E24/F24,"") -> 0.33416667 | H24: 49.95 | I24: =ROUND(H24*F24/E24,0) -> 75 | J24: =IFERROR(1-H24/I24,"") -> 0.334 | K24: =H24-E24 -> 10 | L24: =IFERROR(H24/E24-1,"") -> 0.25031289 | M24: 5 | N24: Compare-at stond op 1,5x (33% korting) en blijft 1,5x
A25: womens-leggings-cargo-pocket-high-waist-biker | B25: Women's Leggings | Cargo Pocket High Waist Biker | C25: leggings | D25: basis | E25: 44.95 | F25: 90 | G25: =IFERROR(1-E25/F25,"") -> 0.50055556 | H25: 49.95 | I25: =ROUND(H25*F25/E25,0) -> 100 | J25: =IFERROR(1-H25/I25,"") -> 0.5005 | K25: =H25-E25 -> 5 | L25: =IFERROR(H25/E25-1,"") -> 0.11123471 | M25: 16
A26: womens-leggings-cargo-pocket-high-waisted | B26: Women's Leggings | Cargo Pocket High Waisted | C26: leggings | D26: basis | E26: 44.95 | F26: 90 | G26: =IFERROR(1-E26/F26,"") -> 0.50055556 | H26: 49.95 | I26: =ROUND(H26*F26/E26,0) -> 100 | J26: =IFERROR(1-H26/I26,"") -> 0.5005 | K26: =H26-E26 -> 5 | L26: =IFERROR(H26/E26-1,"") -> 0.11123471 | M26: 1
A27: womens-leggings-fleece-lined-thermal-winter | B27: Women's Leggings | Fleece Lined Thermal Winter | C27: leggings | D27: basis | E27: 44.95 | F27: 90 | G27: =IFERROR(1-E27/F27,"") -> 0.50055556 | H27: 49.95 | I27: =ROUND(H27*F27/E27,0) -> 100 | J27: =IFERROR(1-H27/I27,"") -> 0.5005 | K27: =H27-E27 -> 5 | L27: =IFERROR(H27/E27-1,"") -> 0.11123471 | M27: 18
A28: womens-leggings-high-waist-zipper-shaping | B28: Women's Leggings | High Waist Zipper Shaping | C28: leggings | D28: basis | E28: 44.95 | F28: 90 | G28: =IFERROR(1-E28/F28,"") -> 0.50055556 | H28: 49.95 | I28: =ROUND(H28*F28/E28,0) -> 100 | J28: =IFERROR(1-H28/I28,"") -> 0.5005 | K28: =H28-E28 -> 5 | L28: =IFERROR(H28/E28-1,"") -> 0.11123471 | M28: 8
A29: womens-leggings-winter-fleece-lined-high-waist | B29: Women's Leggings | Winter Fleece Lined High Waist | C29: leggings | D29: basis | E29: 44.95 | F29: 90 | G29: =IFERROR(1-E29/F29,"") -> 0.50055556 | H29: 49.95 | I29: =ROUND(H29*F29/E29,0) -> 100 | J29: =IFERROR(1-H29/I29,"") -> 0.5005 | K29: =H29-E29 -> 5 | L29: =IFERROR(H29/E29-1,"") -> 0.11123471 | M29: 12
A30: mens-shorts-corduroy-elastic-waist-drawstring | B30: Men's Shorts | Corduroy Elastic Waist Drawstring | C30: mensshorts | D30: basis | E30: 43.95 | F30: 88 | G30: =IFERROR(1-E30/F30,"") -> 0.50056818 | H30: 49.95 | I30: =ROUND(H30*F30/E30,0) -> 100 | J30: =IFERROR(1-H30/I30,"") -> 0.5005 | K30: =H30-E30 -> 6 | L30: =IFERROR(H30/E30-1,"") -> 0.13651877 | M30: 18
A31: mens-shorts-fit-drawstring-corduroy | B31: Men's Shorts | Fit Drawstring Corduroy | C31: mensshorts | D31: basis | E31: 43.95 | F31: 88 | G31: =IFERROR(1-E31/F31,"") -> 0.50056818 | H31: 49.95 | I31: =ROUND(H31*F31/E31,0) -> 100 | J31: =IFERROR(1-H31/I31,"") -> 0.5005 | K31: =H31-E31 -> 6 | L31: =IFERROR(H31/E31-1,"") -> 0.13651877 | M31: 72
A32: mens-shorts-fit-drawstring | B32: Men's Shorts | Fit Drawstring | C32: mensshorts | D32: basis | E32: 48.95 | F32: 98 | G32: =IFERROR(1-E32/F32,"") -> 0.5005102 | H32: 49.95 | I32: =ROUND(H32*F32/E32,0) -> 100 | J32: =IFERROR(1-H32/I32,"") -> 0.5005 | K32: =H32-E32 -> 1 | L32: =IFERROR(H32/E32-1,"") -> 0.020429009 | M32: 30
A33: mens-shorts-floral-print-drawstring | B33: Men's Shorts | Floral Print Drawstring | C33: mensshorts | D33: basis | E33: 49.95 | F33: 100 | G33: =IFERROR(1-E33/F33,"") -> 0.5005 | H33: 49.95 | I33: =ROUND(H33*F33/E33,0) -> 100 | J33: =IFERROR(1-H33/I33,"") -> 0.5005 | K33: =H33-E33 -> 0 | L33: =IFERROR(H33/E33-1,"") -> 0 | M33: 35
A34: womens-tunic-top-long-sleeve-patchwork-ribbed-cuffs | B34: Women's Tunic Top | Long Sleeve Patchwork Ribbed Cuffs | C34: othertops | D34: basis | E34: 47.95 | F34: 96 | G34: =IFERROR(1-E34/F34,"") -> 0.50052083 | H34: 49.95 | I34: =ROUND(H34*F34/E34,0) -> 100 | J34: =IFERROR(1-H34/I34,"") -> 0.5005 | K34: =H34-E34 -> 2 | L34: =IFERROR(H34/E34-1,"") -> 0.041710115 | M34: 24
A35: womens-tunic-blouse-split-v-neck-short-sleeve-side-slit | B35: Women's Tunic Blouse | Split V-Neck Short Sleeve Side Slit | C35: othertops | D35: basis | E35: 49.95 | F35: 100 | G35: =IFERROR(1-E35/F35,"") -> 0.5005 | H35: 49.95 | I35: =ROUND(H35*F35/E35,0) -> 100 | J35: =IFERROR(1-H35/I35,"") -> 0.5005 | K35: =H35-E35 -> 0 | L35: =IFERROR(H35/E35-1,"") -> 0 | M35: 20
A36: womens-tunic-top-v-neck-wrap-denim-short-sleeve | B36: Women's Tunic Top | V-Neck Wrap Denim Short Sleeve | C36: othertops | D36: basis | E36: 49.95 | F36: 100 | G36: =IFERROR(1-E36/F36,"") -> 0.5005 | H36: 49.95 | I36: =ROUND(H36*F36/E36,0) -> 100 | J36: =IFERROR(1-H36/I36,"") -> 0.5005 | K36: =H36-E36 -> 0 | L36: =IFERROR(H36/E36-1,"") -> 0 | M36: 6
... A59: womens-shorts-high-waist-wide-leg-pleated | B59: Women's Shorts | High Waist Wide Leg Pleated | C59: shorts | D59: basis | E59: 47.95 | F59: 96 | G59: =IFERROR(1-E59/F59,"") -> 0.50052083 | H59: 49.95 | I59: =ROUND(H59*F59/E59,0) -> 100 | J59: =IFERROR(1-H59/I59,"") -> 0.5005 | K59: =H59-E59 -> 2 | L59: =IFERROR(H59/E59-1,"") -> 0.041710115 | M59: 55
A60: womens-shorts-high-waist-tummy-control-seamless-fitness | B60: Women's Shorts | High Waist Tummy Control Seamless Fitness | C60: shorts | D60: basis | E60: 49.95 | F60: 36 | G60: =IFERROR(1-E60/F60,"") -> -0.3875 | H60: 49.95 | I60: =ROUND(H60*2,0) -> 100 | J60: =IFERROR(1-H60/I60,"") -> 0.5005 | K60: =H60-E60 -> 0 | L60: =IFERROR(H60/E60-1,"") -> 0 | M60: 28 | N60: FOUT in export: compare-at ($36) lag onder de prijs; voorstel 2x
A61: womens-skirt-midi-leopard-print-wrap-high-slit | B61: Women's Skirt | Midi Leopard Print Wrap High Slit | C61: skirts | D61: basis | E61: 28.95 | F61: 58 | G61: =IFERROR(1-E61/F61,"") -> 0.50086207 | H61: 49.95 | I61: =ROUND(H61*F61/E61,0) -> 100 | J61: =IFERROR(1-H61/I61,"") -> 0.5005 | K61: =H61-E61 -> 21 | L61: =IFERROR(H61/E61-1,"") -> 0.7253886 | M61: 4
A62: womens-skirt-maxi-boho-print-tie-waist-tiered | B62: Women's Skirt | Maxi Boho Print Tie Waist Tiered | C62: skirts | D62: basis | E62: 34.95 | F62: 70 | G62: =IFERROR(1-E62/F62,"") -> 0.50071429 | H62: 49.95 | I62: =ROUND(H62*F62/E62,0) -> 100 | J62: =IFERROR(1-H62/I62,"") -> 0.5005 | K62: =H62-E62 -> 15 | L62: =IFERROR(H62/E62-1,"") -> 0.42918455 | M62: 25
A63: womens-skirt-mini-deep-v-neck-halter-black | B63: Women's Skirt | Mini Deep V-Neck Halter Black | C63: skirts | D63: basis | E63: 34.95 | F63: 70 | G63: =IFERROR(1-E63/F63,"") -> 0.50071429 | H63: 49.95 | I63: =ROUND(H63*F63/E63,0) -> 100 | J63: =IFERROR(1-H63/I63,"") -> 0.5005 | K63: =H63-E63 -> 15 | L63: =IFERROR(H63/E63-1,"") -> 0.42918455 | M63: 4
A64: womens-tiered-skirt-maxi-wrap-v-neck-flutter-sleeve | B64: Women's Tiered Skirt | Maxi Wrap V-Neck Flutter Sleeve | C64: skirts | D64: basis | E64: 38.95 | F64: 78 | G64: =IFERROR(1-E64/F64,"") -> 0.50064103 | H64: 49.95 | I64: =ROUND(H64*F64/E64,0) -> 100 | J64: =IFERROR(1-H64/I64,"") -> 0.5005 | K64: =H64-E64 -> 11 | L64: =IFERROR(H64/E64-1,"") -> 0.28241335 | M64: 18
A65: womens-skirt-midi-spaghetti-strap-fit-and-flare | B65: Women's Skirt | Midi Spaghetti Strap Fit and Flare | C65: skirts | D65: basis | E65: 40.95 | F65: 82 | G65: =IFERROR(1-E65/F65,"") -> 0.50060976 | H65: 49.95 | I65: =ROUND(H65*F65/E65,0) -> 100 | J65: =IFERROR(1-H65/I65,"") -> 0.5005 | K65: =H65-E65 -> 9 | L65: =IFERROR(H65/E65-1,"") -> 0.21978022 | M65: 15
A66: womens-skirt-mini-tiered-ruffle-print | B66: Women's Skirt | Mini Tiered Ruffle Print | C66: skirts | D66: basis | E66: 41.95 | F66: 84 | G66: =IFERROR(1-E66/F66,"") -> 0.50059524 | H66: 49.95 | I66: =ROUND(H66*F66/E66,0) -> 100 | J66: =IFERROR(1-H66/I66,"") -> 0.5005 | K66: =H66-E66 -> 8 | L66: =IFERROR(H66/E66-1,"") -> 0.19070322 | M66: 28
A67: womens-maxi-skirt-denim-button-front-a-line | B67: Women's Maxi Skirt | Denim Button Front A-Line | C67: skirts | D67: basis | E67: 43.95 | F67: 88 | G67: =IFERROR(1-E67/F67,"") -> 0.50056818 | H67: 49.95 | I67: =ROUND(H67*F67/E67,0) -> 100 | J67: =IFERROR(1-H67/I67,"") -> 0.5005 | K67: =H67-E67 -> 6 | L67: =IFERROR(H67/E67-1,"") -> 0.13651877 | M67: 12
A68: womens-maxi-skirt-ruched-bodice-square-neck | B68: Women's Maxi Skirt | Ruched Bodice Square Neck | C68: skirts | D68: basis | E68: 44.95 | F68: 90 | G68: =IFERROR(1-E68/F68,"") -> 0.50055556 | H68: 49.95 | I68: =ROUND(H68*F68/E68,0) -> 100 | J68: =IFERROR(1-H68/I68,"") -> 0.5005 | K68: =H68-E68 -> 5 | L68: =IFERROR(H68/E68-1,"") -> 0.11123471 | M68: 6
A69: womens-skirt-midi-square-neck-sleeveless | B69: Women's Skirt | Midi Square Neck Sleeveless | C69: skirts | D69: basis | E69: 45.95 | F69: 92 | G69: =IFERROR(1-E69/F69,"") -> 0.50054348 | H69: 49.95 | I69: =ROUND(H69*F69/E69,0) -> 100 | J69: =IFERROR(1-H69/I69,"") -> 0.5005 | K69: =H69-E69 -> 4 | L69: =IFERROR(H69/E69-1,"") -> 0.087051143 | M69: 12
A70: womens-skirt-midi-v-neck-empire-waist-long-sleeve | B70: Women's Skirt | Midi V-Neck Empire Waist Long Sleeve | C70: skirts | D70: basis | E70: 45.95 | F70: 92 | G70: =IFERROR(1-E70/F70,"") -> 0.50054348 | H70: 49.95 | I70: =ROUND(H70*F70/E70,0) -> 100 | J70: =IFERROR(1-H70/I70,"") -> 0.5005 | K70: =H70-E70 -> 4 | L70: =IFERROR(H70/E70-1,"") -> 0.087051143 | M70: 12
A71: womens-skirt-mini-ruched-flared-hem-sleeveless | B71: Women's Skirt | Mini Ruched Flared Hem Sleeveless | C71: skirts | D71: basis | E71: 46.95 | F71: 94 | G71: =IFERROR(1-E71/F71,"") -> 0.50053191 | H71: 49.95 | I71: =ROUND(H71*F71/E71,0) -> 100 | J71: =IFERROR(1-H71/I71,"") -> 0.5005 | K71: =H71-E71 -> 3 | L71: =IFERROR(H71/E71-1,"") -> 0.063897764 | M71: 60
...
